Workbook

Sheet 发射纪录
A1: 总数 | B1: 长征 | C1: 其他 | D1: 火箭 | E1: 遥号 | F1: 载荷 | G1: 日期 | H1: 时间 （UTC+8） | I1: 轨道 | J1: 地点 | K1: 工位 | L1: 同地相 隔日数 | M1: 同箭相 隔日数 | N1: 结果 | O1: 备注
A2: 1 | B2: 1 | C2: - | D2: 长征一号 | E2: 遥4 | F2: 东方红一号卫星 | G2: 25682 | H2: 21时35分44.7秒 | I2: 椭圆轨道 | J2: 酒泉 | K2: 5020 | N2: 成功
A3: 2 | B3: 2 | C3: - | D3: 长征一号 | F3: 实践一号 | G3: 25995 | H3: 20时03分 | I3: 椭圆轨道 | J3: 酒泉 | K3: 5020 | L3: 313 | M3: 313 | N3: 成功
A4: 3 | B4: - | C4: 1 | D4: 风暴一号 | E4: 2703X | F4: 长空一号电子侦察卫星 | G4: 26925 | H4: 20时12分 | I4: 近地轨道 | J4: 酒泉 | K4: 138 | L4: 930 | N4: 失败
A5: 4 | B5: - | C5: 2 | D5: 风暴一号 | F5: 长空一号电子侦察卫星 | G5: 27222 | H5: 21时55分 | I5: 近地轨道 | J5: 酒泉 | K5: 138 | L5: 297 | M5: 297 | N5: 失败
A6: 5 | B6: 3 | C6: - | D6: 长征二号 | E6: 遥3 | F6: 尖兵一号国土普查卫星00星 | G6: 27338 | H6: 17时40分 | I6: 近地轨道 | J6: 酒泉 | K6: 138 | L6: 116 | N6: 失败
A7: 6 | B7: - | C7: 3 | D7: 风暴一号 | F7: 长空一号电子侦察卫星 | G7: 27601 | H7: 21时30分 | I7: 近地轨道 | J7: 酒泉 | K7: 138 | L7: 263 | M7: 379 | N7: 成功
A8: 7 | B8: 4 | C8: - | D8: 长征二号甲 | E8: 遥4 | F8: 尖兵一号国土普查卫星01星 | G8: 27724 | H8: 11时29分52秒 | I8: 近地轨道 | J8: 酒泉 | K8: 138 | L8: =G8-G7 -> 123 | N8: 成功
A9: 8 | B9: - | C9: 4 | D9: 风暴一号 | F9: 长空一号电子侦察卫星 | G9: 27744 | H9: 17时21分 | I9: 近地轨道 | J9: 酒泉 | K9: 138 | L9: 20 | M9: 143 | N9: 成功
A10: 9 | B10: - | C10: 5 | D10: 风暴一号 | F10: 长空一号电子侦察卫星 | G10: 28002 | H10: 19时45分 | I10: 近地轨道 | J10: 酒泉 | K10: 138 | L10: 258 | M10: 258 | N10: 成功
A11: 10 | B11: - | C11: 6 | D11: 风暴一号 | F11: 长空一号电子侦察卫星 | G11: 28074 | H11: 17时05分 | I11: 近地轨道 | J11: 酒泉 | K11: 138 | L11: 72 | M11: 72 | N11: 失败
A12: 11 | B12: 5 | C12: - | D12: 长征二号甲 | E12: 遥5 | F12: 尖兵一号国土普查卫星02星 | G12: 28101 | H12: 12时38分 | I12: 近地轨道 | J12: 酒泉 | K12: 138 | L12: 27 | M12: 377 | N12: 成功
A13: 12 | B13: 6 | C13: - | D13: 长征二号甲 | E13: 遥6 | F13: 尖兵一号国土普查卫星03星 | G13: 28516 | H13: 12时58分 | I13: 近地轨道 | J13: 酒泉 | K13: 138 | L13: 415 | M13: 415 | N13: 成功
A14: 13 | B14: - | C14: 7 | D14: 风暴一号 | E14: 8701 | F14: 实践二号,实践二号甲,实践二号乙 | G14: 29064 | H14: 05时28分 | I14: 近地轨道 | J14: 酒泉 | K14: 138 | L14: 548 | M14: 990 | N14: 失败
A15: 14 | B15: - | C15: 8 | D15: 风暴一号 | E15: 1802 | F15: 实践二号 | G15: 29849 | H15: 05时28分39.857秒 | I15: 近地轨道 | J15: 酒泉 | K15: 138 | L15: 785 | M15: 785 | N15: 成功
A16: 15 | B16: 7 | C16: - | D16: 长征二号丙 | E16: 遥1 | F16: 尖兵一号国土普查卫星04星 | G16: 30203 | H16: 15时19分 | I16: 近地轨道 | J16: 酒泉 | K16: 138 | L16: 354 | N16: 成功
A17: 16 | B17: 8 | C17: - | D17: 长征二号丙 | E17: 遥2 | F17: 尖兵一号国土普查卫星05星 | G17: 30547 | H17: 14时00分 | I17: 近地轨道 | J17: 酒泉 | K17: 138 | L17: 344 | M17: 344 | N17: 成功
A18: 17 | B18: 9 | C18: - | D18: 长征三号 | E18: 遥1 | F18: 东方红二号试验通信卫星 | G18: 30710 | H18: 20时25分 | I18: 地球同步转移轨道 | J18: 西昌 | K18: 3 | N18: 部分成功
A19: 18 | B19: 10 | C19: - | D19: 长征三号 | E19: 遥2 | F19: 东方红二号试验通信卫星 | G19: 30780 | H19: 19时20分02秒 | I19: 地球同步转移轨道 | J19: 西昌 | K19: 3 | L19: 70 | M19: 70 | N19: 成功
A20: 19 | B20: 11 | C20: - | D20: 长征二号丙 | E20: 遥3 | F20: 尖兵一号国土普查卫星06星 | G20: 30937 | H20: 13时44分 | I20: 近地轨道 | J20: 酒泉 | K20: 138 | L20: 390 | M20: 390 | N20: 成功
A21: 20 | B21: 12 | C21: - | D21: 长征二号丙 | E21: 遥4 | F21: 尖兵一号国土普查卫星07星 | G21: 31341 | H21: 13时04分 | I21: 近地轨道 | J21: 酒泉 | K21: 138 | L21: 404 | M21: 404 | N21: 成功
A22: 21 | B22: 13 | C22: - | D22: 长征三号 | E22: 遥3 | F22: 东方红二号通信卫星 | G22: 31444 | H22: 20时36分 | I22: 地球同步转移轨道 | J22: 西昌 | K22: 3 | L22: 664 | M22: 664 | N22: 成功
A23: 22 | B23: 14 | C23: - | D23: 长征二号丙 | E23: 遥5 | F23: 尖兵一号国土普查卫星08星 | G23: 31691 | H23: 13时40分 | I23: 近地轨道 | J23: 酒泉 | K23: 138 | L23: 350 | M23: 350 | N23: 成功
A24: 23 | B24: 15 | C24: - | D24: 长征二号丙 | E24: 遥6 | F24: 尖兵一号国土普查卫星09星 | G24: 31994 | H24: 15时39分(UTC+9) | I24: 近地轨道 | J24: 酒泉 | K24: 138 | L24: 303 | M24: 303 | N24: 成功
A25: 24 | B25: 16 | C25: - | D25: 长征二号丙 | E25: 遥7 | F25: 尖兵一号甲摄影测绘卫星01星 | G25: 32029 | H25: 16时15分(UTC+9) | I25: 近地轨道 | J25: 酒泉 | K25: 138 | L25: 35 | M25: 35 | N25: 成功
A26: 25 | B26: 17 | C26: - | D26: 长征三号 | E26: 遥4 | F26: 东方红二号甲通信卫星 | G26: 32209 | H26: 20时41分 | I26: 地球同步转移轨道 | J26: 西昌 | K26: 3 | L26: 765 | M26: 765 | N26: 成功
A27: 26 | B27: 18 | C27: - | D27: 长征二号丙 | E27: 遥8 | F27: 尖兵一号甲摄影测绘卫星02星 | G27: 32360 | H27: 16时28分35秒(UTC+9) | I27: 近地轨道 | J27: 酒泉 | K27: 138 | L27: 331 | M27: 331 | N27: 成功
A28: 27 | B28: 19 | C28: - | D28: 长征四号甲 | E28: 遥1 | F28: 风云一号A(01) | G28: 32393 | H28: 05时30分19秒(UTC+9) | I28: 太阳同步轨道 | J28: 太原 | K28: 7 | N28: 成功
A29: 28 | B29: 20 | C29: - | D29: 长征三号 | E29: 遥5 | F29: 中星2 | G29: 32499 | H29: 20时40分 | I29: 地球同步转移轨道 | J29: 西昌 | K29: 3 | L29: 290 | M29: 290 | N29: 成功
A30: 29 | B30: 21 | C30: - | D30: 长征三号 | E30: 遥6 | F30: 中星3 | G30: 32908 | H30: 20时27分03秒 | I30: 地球同步转移轨道 | J30: 西昌 | K30: 3 | L30: 409 | M30: 409 | N30: 成功
A31: 30 | B31: 22 | C31: - | D31: 长征三号 | E31: 遥7 | F31: 亚卫一号通信卫星 | G31: 32970 | H31: 21时30分02.281秒 | I31: 地球同步转移轨道 | J31: 西昌 | K31: 3 | L31: 62 | M31: 62 | N31: 成功
A32: 31 | B32: 23 | C32: - | D32: 长征二号捆 | E32: 遥1 | F32: 巴达尔A科学实验卫星 | G32: 33070 | H32: 09时40分(UTC+9) | I32: 椭圆轨道 | J32: 西昌 | K32: 2 | L32: 100 | N32: 成功
A33: 32 | B33: 24 | C33: - | D33: 长征四号甲 | E33: 遥2 | F33: 风云一号B(02) | G33: 33119 | H33: 09时53分(UTC+9) | I33: 太阳同步轨道 | J33: 太原 | K33: 7 | L33: 726 | M33: 726 | N33: 成功
A34: 33 | B34: 25 | C34: - | D34: 长征二号丙 | E34: 遥9 | F34: 返回式遥感1号03 | G34: 33151 | H34: 14时15分 | I34: 近地轨道 | J34: 酒泉 | K34: 138 | L34: 791 | M34: 791 | N34: 成功
A35: 34 | B35: 26 | C35: - | D35: 长征三号 | E35: 遥9 | F35: 中星4 | G35: 33600 | H35: 20时02分 | I35: 地球同步转移轨道 | J35: 西昌 | K35: 3 | L35: 530 | M35: 630 | N35: 失败
A36: - | B36: - | C36: - | D36: 长征二号捆 | E36: 遥2 | F36: 澳星B1通信卫星 | G36: 33685 | H36: 18时40分 | I36: 椭圆轨道 | J36: 西昌 | K36: 2 | L36: 85 | M36: 615 | N36: 中止
A37: 35 | B37: 27 | C37: - | D37: 长征二号丁 | E37: 遥1 | F37: 返回式遥感2号01 | G37: 33825 | H37: 16时00分 | I37: 近地轨道 | J37: 酒泉 | K37: 138 | L37: 674 | N37: 成功
A38: 36 | B38: 28 | C38: - | D38: 长征二号捆 | E38: 遥3 | F38: 澳星B1通信卫星 | G38: 33830 | H38: 07时00分 | I38: 椭圆轨道 | J38: 西昌 | K38: 2 | L38: 145 | M38: 145 | N38: 成功
A39: 37 | B39: 29 | C39: - | D39: 长征二号丙 | E39: 遥10 | F39: 返回式遥感1号04 | G39: 33883 | H39: 14时20分05秒 | I39: 近地轨道 | J39: 酒泉 | K39: 138 | L39: 58 | M39: 732 | N39: 成功
A40: 38 | B40: 30 | C40: - | D40: 长征二号捆 | E40: 遥4 | F40: 澳星B2通信卫星 | G40: 33959 | H40: 19时20分05.466秒 | I40: 椭圆轨道 | J40: 西昌 | K40: 2 | L40: 129 | M40: 129 | N40: 部分成功
...

Sheet 发射预测
A1: =_xlfn.CONCAT("截止",TEXT(TODAY(),"YYYY年MM月DD日"),"：全年成功",年間統計!O60,"/",年間統計!N60,"发射=",IF(年間統計!N60=0,"无发射",TEXT(年間統計!O60/年間統計!N60,"0.00%成功率， ")),MONTH(TODAY()),"月成功",月間統計!O682,"/",月間統計!N682,"发射=",TEXT(月間統計!O682/月間統計!N682,"0.00%成功率")) -> 截止2026年07月06日：全年成功44/47发射=93.62%成功率, 7月成功3/3发射=100.00%成功率 | G1: HYDROPAC /26 BAY OF BENGAL. BURMA/NAVAREA Navigational Warnings
A2: 标色均根据航警！确定日期时间的99.99%可能！范围日期每一天都可能，时间也不确定，甚至取消！ | G2: 楚天一号002-004，楚天二号03,开运二号
A3: 虚线表示其中之一可能！载荷完全瞎猜不需多问！知道的都在此表，没有的就是不知道！
A4: 运载火箭名称（遥号） | B4: 有效载荷名称 | C4: 发射日期（UTC+8） | D4: 发射轨道 | E4: 发射地点
A5: 长征十号乙（遥1） | B5: 星网低轨23(一级回收验证) | C5: 46213 | D5: 近地轨道 | E5: 海南商业航天发射场
C6: 13时20分
A7: 捷龙三号（遥12） | B7: 东方慧眼高光谱01(东方星链05/金山号) | C7: 2026年7月12-15日 | D7: 太阳同步轨道 | E7: 黄海海阳东方航天港号 36.61667N,121.18333E (太原卫星发射中心组织)
B8: 东方慧眼高光谱02(东方星链06/银山号) | C8: 约11时00分
A9: 引力一号（遥3） | B9: 西光贰号01(彩云高光谱01)
A10: 长征七号甲（遥17） | B10: 通信技术试验二十六号B | C10: 2026年7月17-20日 | D10: 地月转移轨道 | E10: 文昌航天发射场
C11: 约20时00分
A12: 长征三号乙（遥118） | B12: 实践三十二号B | C12: 2026年7月23-26日 | D12: 地球同步转移轨道 | E12: 西昌卫星发射中心
C13: 约20时00分
A14: 以下全部待定未定不定，随时变更甚至取消，仅供参考无需关注再问！
A15: 朱雀三号（遥2） | B15: -(一级回收验证) | C15: 46218 | D15: 太阳同步轨道 | E15: 酒泉卫星发射中心
A17: 力箭一号（遥15） | B17: 5星 | C17: 46221 | D17: 太阳同步轨道 | E17: 酒泉卫星发射中心
A19: 长征十二号（遥8） | B19: 星网低轨24A-I | C19: 46223 | D19: 近地轨道 | E19: 海南商业航天发射场
A21: 谷神星一号海（遥8） | B21: 中国移动03 | C21: 46224 | D21: 近地轨道 | E21: 黄海海阳东方航天港号 36.61667N,121.18333E (太原卫星发射中心组织)
A24: 长征二号丁（遥104） | B24: - | C24: 46225 | D24: 太阳同步轨道 | E24: 酒泉卫星发射中心
A26: 长征六号甲（遥27） | B26: 千帆极轨16A-R | C26: 46227 | D26: 极地轨道 | E26: 太原卫星发射中心
A28: 快舟十一号（遥12） | B28: 迪迩六号(B300-L03) 迪迩十一号(B300-F01) | C28: 46229 | D28: 太阳同步轨道 | E28: 酒泉卫星发射中心
A30: 致航一号（遥1） | B30: 首飞 | C30: 46231 | D30: 近地轨道 | E30: 酒泉卫星发射中心
A32: 长征八号甲（遥10） | B32: 千帆极轨14A-Y | C32: 46233 | D32: 近地轨道 | E32: 海南商业航天发射场
A34: 引力一号（遥4） | B34: 锋行一号 西光贰号01(彩云高光谱01) 雄安一号(鸿鹄03号) 东坡13,东坡14(西南财经大学号) 东坡17-20 | C34: 46234 | D34: 近地轨道 | E34: 黄海海阳东方航天港号 36.61667N,121.18333E (太原卫星发射中心组织)
A39: 智神星一号（遥1） | B39: 定制化试验载荷 | C39: 46234 | D39: 太阳同步轨道 | E39: 酒泉卫星发射中心
A41: 力箭一号海（遥1） | B41: 首飞 | C41: 46235 | D41: 近地轨道 | E41: 黄海海阳东方航天港号 36.61667N,121.18333E (太原卫星发射中心组织)
... A76: 长征十号甲（遥1）/立巡一号（遥1） | B76: 首飞 | C76: 46052 | D76: 地月转移轨道 | E76: 文昌航天发射场
B77: 时空基准
A78: 长征十二号海（遥1） | B78: 首飞 | C78: 46052 | D78: 近地轨道 | E78: 黄海海阳东方航天港号 36.61667N,121.18333E (太原卫星发射中心组织)
A81: 长征三号乙（遥118） | B81: 风云四号D | C81: 46052 | D81: 地球同步转移轨道 | E81: 西昌卫星发射中心
A83: 长征四号丙（遥） | B83: 风云三号I | C83: 46387 | D83: 太阳同步轨道 | E83: 西昌卫星发射中心
A85: 元行者一号（遥1） | B85: 首飞 | C85: 46386 | D85: 近地轨道 | E85: 黄海海阳东方航天港号 36.44717°N,121.19633°E (太原卫星发射中心组织)
A88: 赤兔一号（遥1） | B88: 首飞 | C88: 46386 | D88: 太阳同步轨道 | E88: 酒泉卫星发射中心
A90: 腾龙一号（遥1） | B90: 首飞 | C90: 46386 | D90: 太阳同步轨道 | E90: 酒泉卫星发射中心
A92: 星空一号（遥1） | B92: 首飞 | C92: 46386 | D92: 太阳同步轨道 | E92: 酒泉卫星发射中心
A94: 智龙三号（遥1） | B94: 首飞 | C94: 46386 | D94: 太阳同步轨道 | E94: 酒泉卫星发射中心
A96: 长征五号乙（遥） | B96: 空间站巡天光学舱 | C96: 46441 | D96: 近地轨道 | E96: 文昌航天发射场

Sheet 发射时间预测
A1: =HYPERLINK("#火箭年間統計!A2","火箭年間统计") -> 火箭年間统计 | B1: 发射地 | C1: FIR | E1: UTC | J1: UTC+8
C2: Location | D2: Number | E2: Start | F2: End | J2: Start+8 | K2: Diff | L2: 预测发射时间 | M2: 实际发射时间
A3: 长征二号丙 | B3: 酒泉 | C3: ZLHW | E3: 44680.169 | F3: 44680.19 | J3: =E3+TIME(8,0,0) -> 44680.502 | K3: =IF($M$3-J3<0,"-"&TEXT(ABS($M$3-J3),"[hh]:mm:ss"),TEXT($M$3-J3,"[hh]:mm:ss")) -> 00:08:33 | L3: 0 | M3: 44680.508
A4: 长征二号丙 远征一号商 | B4: 酒泉 | C4: ZLHW | E4: 44701.431 | F4: 44701.455 | J4: =E4+TIME(8,0,0) -> 44701.764 | K4: =IF($M$4-J4<0, "-" & TEXT(ABS($M$4-J4),"[hh]:mm:ss"), TEXT($M$4-J4,"[hh]:mm:ss")) -> 00:10:00 | L4: 44701.771 | M4: 44701.771
E5: 44701.432 | F5: 44701.458 | J5: =E5+TIME(8,0,0) -> 44701.765 | K5: =IF($M$4-J5<0, "-" & TEXT(ABS($M$4-J5),"[hh]:mm:ss"), TEXT($M$4-J5,"[hh]:mm:ss")) -> 00:08:00
C6: ZLHW/ZPKM | E6: 44701.433 | F6: 44701.463 | J6: =E6+TIME(8,0,0) -> 44701.766 | K6: =IF($M$4-J6<0, "-" & TEXT(ABS($M$4-J6),"[hh]:mm:ss"), TEXT($M$4-J6,"[hh]:mm:ss")) -> 00:07:00
C7: YMMM | E7: 44701.442 | F7: 44701.501 | J7: =E7+TIME(8,0,0) -> 44701.775 | K7: =IF($M$4-J7<0, "-" & TEXT(ABS($M$4-J7),"[hh]:mm:ss"), TEXT($M$4-J7,"[hh]:mm:ss")) -> -00:06:00
A8: 长征二号丙 | B8: 酒泉 | C8: ZLHW | E8: 44981.162 | F8: 44981.183 | J8: =E8+TIME(8,0,0) -> 44981.496 | K8: =IF($M$8-J8<0, "-" & TEXT(ABS($M$8-J8),"[hh]:mm:ss"), TEXT($M$8-J8,"[hh]:mm:ss")) -> 00:07:00 | L8: 44981.503 | M8: 44981.501
A9: 长征二号丙 | B9: 酒泉 | C9: ZLHW | E9: 44998.162 | F9: 44998.178 | J9: =E9+TIME(8,0,0) -> 44998.495 | K9: =IF($M$9-J9<0, "-" & TEXT(ABS($M$9-J9),"[hh]:mm:ss"), TEXT($M$9-J9,"[hh]:mm:ss")) -> 00:09:00 | L9: 44998.501 | M9: 44998.501
E10: 44998.162 | F10: 44998.184 | J10: =E10+TIME(8,0,0) -> 44998.496 | K10: =IF($M$9-J10<0, "-" & TEXT(ABS($M$9-J10),"[hh]:mm:ss"), TEXT($M$9-J10,"[hh]:mm:ss")) -> 00:08:00
A11: 长征二号丙 | B11: 酒泉 | C11: ZBPE | E11: 45067.326 | F11: 45067.428 | J11: =E11+TIME(8,0,0) -> 45067.66 | K11: =IF($M$11-J11<0, "-" & TEXT(ABS($M$11-J11),"[hh]:mm:ss"), TEXT($M$11-J11,"[hh]:mm:ss")) -> 00:10:00 | L11: 45067.693 | M11: 45067.667
A12: 长征二号丙 远征一号商 | B12: 酒泉 | C12: YMMM | E12: 45116.456 | F12: 45116.522 | J12: =E12+TIME(8,0,0) -> 45116.79 | K12: =IF($M$12-J12<0, "-" & TEXT(ABS($M$12-J12),"[hh]:mm:ss"), TEXT($M$12-J12,"[hh]:mm:ss")) -> 00:03:00 | L12: 45116.811 | M12: 45116.792
A13: 长征二号丙 远征一号商 | B13: 酒泉 | C13: ZLHW | D13: A3609/23 | E13: 45246.159 | F13: 45246.178 | J13: =E13+TIME(8,0,0) -> 45246.492 | K13: =IF($M$13-J13<0, "-" & TEXT(ABS($M$13-J13),"[hh]:mm:ss"), TEXT($M$13-J13,"[hh]:mm:ss")) -> 00:06:00 | L13: 45246.5 | M13: 45246.497
C14: YMMM | D14: F3793/23 | E14: 45246.162 | F14: 45246.187 | J14: =E14+TIME(8,0,0) -> 45246.495 | K14: =IF($M$13-J14<0, "-" & TEXT(ABS($M$13-J14),"[hh]:mm:ss"), TEXT($M$13-J14,"[hh]:mm:ss")) -> 00:02:00
A15: 长征二号丙 | B15: 酒泉 | C15: ZLHW | D15: A3826/23 | E15: 45264.168 | F15: 45264.184 | J15: =E15+TIME(8,0,0) -> 45264.501 | K15: =IF($M$15-J15<0, "-" & TEXT(ABS($M$15-J15),"[hh]:mm:ss"), TEXT($M$15-J15,"[hh]:mm:ss")) -> 00:08:00 | L15: 45264.507 | M15: 45264.507
D16: A3827/23 | E16: 45264.168 | F16: 45264.189 | J16: =E16+TIME(8,0,0) -> 45264.501 | K16: =IF($M$15-J16<0, "-" & TEXT(ABS($M$15-J16),"[hh]:mm:ss"), TEXT($M$15-J16,"[hh]:mm:ss")) -> 00:08:00
A17: 长征二号丙 远征一号商 | B17: 酒泉 | C17: ZLHW | D17: A4096/23 | E17: 45290.003 | F17: 45290.017 | J17: =E17+TIME(8,0,0) -> 45290.336 | K17: =IF($M$17-J17<0, "-" & TEXT(ABS($M$17-J17),"[hh]:mm:ss"), TEXT($M$17-J17,"[hh]:mm:ss")) -> 00:09:00 | L17: 45290.34 | M17: 45290.342
D18: A4097/23 | E18: 45290.004 | F18: 45290.022 | J18: =E18+TIME(8,0,0) -> 45290.338 | K18: =IF($M$17-J18<0, "-" & TEXT(ABS($M$17-J18),"[hh]:mm:ss"), TEXT($M$17-J18,"[hh]:mm:ss")) -> 00:07:00
C19: YBBB | D19: N4392/23 | E19: 45290.006 | F19: 45290.034 | J19: =E19+TIME(8,0,0) -> 45290.34 | K19: =IF($M$17-J19<0, "-" & TEXT(ABS($M$17-J19),"[hh]:mm:ss"), TEXT($M$17-J19,"[hh]:mm:ss")) -> 00:04:00
A20: 长征二号丙 | B20: 酒泉 | C20: ZLHW | D20: A3732/24 | E20: 45605.145 | F20: 45605.162 | J20: =E20+TIME(8,0,0) -> 45605.478 | K20: =IF($M$20-J20<0, "-" & TEXT(ABS($M$20-J20),"[hh]:mm:ss"), TEXT($M$20-J20,"[hh]:mm:ss")) -> 00:10:00 | L20: 45605.484 | M20: 45605.485
A21: 长征二号丙 | B21: 酒泉 | C21: ZLHW | D21: A4009/24 | E21: 45650.976 | F21: 45650.999 | J21: =E21+TIME(8,0,0) -> 45651.31 | K21: =IF($M$21-J21<0, "-" & TEXT(ABS($M$21-J21),"[hh]:mm:ss"), TEXT($M$21-J21,"[hh]:mm:ss")) -> 00:13:00 | L21: 45651.317 | M21: 45651.319
A22: 长征二号丙 | B22: 酒泉 | C22: ZLHW | D22: A0409/25 | E22: 45715.292 | F22: 45715.312 | J22: =E22+TIME(8,0,0) -> 45715.626 | K22: =IF($M$22-J22<0, "-" & TEXT(ABS($M$22-J22),"[hh]:mm:ss"), TEXT($M$22-J22,"[hh]:mm:ss")) -> 00:07:00 | L22: 45715.631 | M22: 45715.631
A23: 长征二号丙 远征一号商 | B23: 酒泉 | C23: ZLHW | D23: A3126/25 | E23: 45916.04 | F23: 45916.059 | J23: =E23+TIME(8,0,0) -> 45916.374 | K23: =IF($M$23-J23<0, "-" & TEXT(ABS($M$23-J23),"[hh]:mm:ss"), TEXT($M$23-J23,"[hh]:mm:ss")) -> 00:08:00 | L23: 45916.38 | M23: 45916.379
D24: A3127/25 | E24: 45916.041 | F24: 45916.064 | J24: =E24+TIME(8,0,0) -> 45916.374 | K24: =IF($M$23-J24<0, "-" & TEXT(ABS($M$23-J24),"[hh]:mm:ss"), TEXT($M$23-J24,"[hh]:mm:ss")) -> 00:07:00
C25: YBBB | D25: D6018/25 | E25: 45916.044 | F25: 45916.074 | J25: =E25+TIME(8,0,0) -> 45916.377 | K25: =IF($M$23-J25<0, "-" & TEXT(ABS($M$23-J25),"[hh]:mm:ss"), TEXT($M$23-J25,"[hh]:mm:ss")) -> 00:03:00
A26: 长征二号丙 | B26: 酒泉 | C26: ZLHW | D26: A4301/25 | E26: 45980.161 | F26: 45980.18 | J26: =E26+TIME(8,0,0) -> 45980.494 | K26: =IF($M$26-J26<0, "-" & TEXT(ABS($M$26-J26),"[hh]:mm:ss"), TEXT($M$26-J26,"[hh]:mm:ss")) -> 00:09:00 | L26: 45980.5 | M26: 45980.501
D27: A4302/25 | E27: 45980.162 | F27: 45980.185 | J27: =E27+TIME(8,0,0) -> 45980.495 | K27: =IF($M$26-J27<0, "-" & TEXT(ABS($M$26-J27),"[hh]:mm:ss"), TEXT($M$26-J27,"[hh]:mm:ss")) -> 00:08:00
A28: 长征二号丙 | B28: 酒泉 | C28: ZLHW | D28: A0114/26 | E28: 46037.162 | F28: 46037.178 | J28: =E28+TIME(8,0,0) -> 46037.495 | K28: =IF($M$28-J28<0, "-" & TEXT(ABS($M$28-J28),"[hh]:mm:ss"), TEXT($M$28-J28,"[hh]:mm:ss")) -> 00:08:00 | L28: 46037.501 | M28: 46037.501
D29: A0115/26 | E29: 46037.162 | F29: 46037.184 | J29: =E29+TIME(8,0,0) -> 46037.496 | K29: =IF($M$28-J29<0, "-" & TEXT(ABS($M$28-J29),"[hh]:mm:ss"), TEXT($M$28-J29,"[hh]:mm:ss")) -> 00:07:00
A30: 长征二号丙 | B30: 酒泉 | C30: ZLHW | D30: A0336/26 | E30: 46053.162 | F30: 46053.184 | J30: =E30+TIME(8,0,0) -> 46053.496 | K30: =IF($M$30-J30<0, "-" & TEXT(ABS($M$30-J30),"[hh]:mm:ss"), TEXT($M$30-J30,"[hh]:mm:ss")) -> 00:07:00 | L30: 46053.501 | M30: 46053.501
A31: 长征二号丙 远征一号商 | B31: 酒泉 | C31: ZLHW | D31: A0763/26 | E31: 46108.169 | F31: 46108.193 | J31: =E31+TIME(8,0,0) -> 46108.503 | K31: =IF($M$31-J31<0, "-" & TEXT(ABS($M$31-J31),"[hh]:mm:ss"), TEXT($M$31-J31,"[hh]:mm:ss")) -> 00:07:00 | L31: 46108.508 | M31: 46108.508
C32: YMMM | D32: F1145/26 | E32: 46108.172 | F32: 46108.202 | J32: =E32+TIME(8,0,0) -> 46108.506 | K32: =IF($M$31-J32<0, "-" & TEXT(ABS($M$31-J32),"[hh]:mm:ss"), TEXT($M$31-J32,"[hh]:mm:ss")) -> 00:03:00
C33: PAC | D33: 895/26 | E33: 46108.172 | F33: 46108.375 | J33: =E33+TIME(8,0,0) -> 46108.506 | K33: =IF($M$31-J33<0, "-" & TEXT(ABS($M$31-J33),"[hh]:mm:ss"), TEXT($M$31-J33,"[hh]:mm:ss")) -> 00:03:00
A34: 长征二号丙 | B34: 酒泉 | J34: =E34+TIME(8,0,0) -> 0.33333333 | K34: =IF($M$34-J34<0, "-" & TEXT(ABS($M$34-J34),"[hh]:mm:ss"), TEXT($M$34-J34,"[hh]:mm:ss")) -> -08:00:00
J35: =E35+TIME(8,0,0) -> 0.33333333 | K35: =IF($M$34-J35<0, "-" & TEXT(ABS($M$34-J35),"[hh]:mm:ss"), TEXT($M$34-J35,"[hh]:mm:ss")) -> -08:00:00
A37: 长征二号丙 | B37: 西昌 | C37: ZPKM | D37: A0746/20 | E37: 43914.149 | F37: 43914.162 | J37: =E37+TIME(8,0,0) -> 43914.483 | K37: =IF($M$37-J37<0, "-" & TEXT(ABS($M$37-J37),"[hh]:mm:ss"), TEXT($M$37-J37,"[hh]:mm:ss")) -> 00:08:00 | L37: 43914.488 | M37: 43914.488
C38: ZGZU | D38: A0747/20 | E38: 43914.15 | F38: 43914.163 | J38: =E38+TIME(8,0,0) -> 43914.483 | K38: =IF($M$37-J38<0, "-" & TEXT(ABS($M$37-J38),"[hh]:mm:ss"), TEXT($M$37-J38,"[hh]:mm:ss")) -> 00:07:00
A39: 长征二号丙 | B39: 西昌 | C39: ZPKM | E39: 44625.243 | F39: 44625.267 | J39: =E39+TIME(8,0,0) -> 44625.576 | K39: =IF($M$39-J39<0, "-" & TEXT(ABS($M$39-J39),"[hh]:mm:ss"), TEXT($M$39-J39,"[hh]:mm:ss")) -> 00:11:00 | L39: 44625.587 | M39: 44625.584
C40: ZJSA | E40: 44625.246 | F40: 44625.278 | J40: =E40+TIME(8,0,0) -> 44625.579 | K40: =IF($M$39-J40<0, "-" & TEXT(ABS($M$39-J40),"[hh]:mm:ss"), TEXT($M$39-J40,"[hh]:mm:ss")) -> 00:07:00
A41: 长征二号丙 | B41: 西昌 | C41: ZPKM | E41: 44714.16 | F41: 44714.177 | J41: =E41+TIME(8,0,0) -> 44714.493 | K41: =IF($M$41-J41<0, "-" & TEXT(ABS($M$41-J41),"[hh]:mm:ss"), TEXT($M$41-J41,"[hh]:mm:ss")) -> 00:10:00 | L41: 44714.5 | M41: 44714.5
...

Sheet 火箭年間統計
A1: =CONCATENATE("截止",YEAR(TODAY()),"年",MONTH(TODAY()),"月",DAY(TODAY()),"日") -> 截止2026年7月6日
A2: 发射地链接 | G2: {=HYPERLINK("#发射时间预测!" & ADDRESS(MAX(IF((发射时间预测!$A:$A=TRIM(CLEAN(G6)))*(发射时间预测!$B:$B="酒泉"), ROW(发射时间预测!$A:$A))), 1), "酒泉")} -> 酒泉 | H2: {=HYPERLINK("#发射时间预测!" & ADDRESS(MAX(IF((发射时间预测!$A:$A=TRIM(CLEAN(H6)))*(发射时间预测!$B:$B="酒泉"), ROW(发射时间预测!$A:$A))), 1), "酒泉")} -> 酒泉 | J2: {=HYPERLINK("#发射时间预测!" & ADDRESS(MAX(IF((发射时间预测!$A:$A=TRIM(CLEAN(J6)))*(发射时间预测!$B:$B="酒泉"), ROW(发射时间预测!$A:$A))), 1), "酒泉")} -> 酒泉 | M2: {=HYPERLINK("#发射时间预测!" & ADDRESS(MAX(IF((发射时间预测!$A:$A=TRIM(CLEAN(M6)))*(发射时间预测!$B:$B="西昌"), ROW(发射时间预测!$A:$A))), 1), "西昌")} -> 西昌 | N2: {=HYPERLINK("#发射时间预测!" & ADDRESS(MAX(IF((发射时间预测!$A:$A=TRIM(CLEAN(N6)))*(发射时间预测!$B:$B="西昌"), ROW(发射时间预测!$A:$A))), 1), "西昌")} -> 西昌 | P2: {=HYPERLINK("#发射时间预测!" & ADDRESS(MAX(IF((发射时间预测!$A:$A=TRIM(CLEAN(P6)))*(发射时间预测!$B:$B="酒泉"), ROW(发射时间预测!$A:$A))), 1), "酒泉")} -> 酒泉 | Q2: {=HYPERLINK("#发射时间预测!" & ADDRESS(MAX(IF((发射时间预测!$A:$A=TRIM(CLEAN(Q6)))*(发射时间预测!$B:$B="酒泉"), ROW(发射时间预测!$A:$A))), 1), "酒泉")} -> 酒泉 | R2: {=HYPERLINK("#发射时间预测!" & ADDRESS(MAX(IF((发射时间预测!$A:$A=TRIM(CLEAN(R6)))*(发射时间预测!$B:$B="文昌"), ROW(发射时间预测!$A:$A))), 1), "文昌")} -> 文昌 | S2: {=HYPERLINK("#发射时间预测!" & ADDRESS(MAX(IF((发射时间预测!$A:$A=TRIM(CLEAN(S6)))*(发射时间预测!$B:$B="文昌"), ROW(发射时间预测!$A:$A))), 1), "文昌")} -> 文昌 | T2: {=HYPERLINK("#发射时间预测!" & ADDRESS(MAX(IF((发射时间预测!$A:$A=TRIM(CLEAN(T6)))*(发射时间预测!$B:$B="太原"), ROW(发射时间预测!$A:$A))), 1), "太原")} -> 太原 | U2: {=HYPERLINK("#发射时间预测!" & ADDRESS(MAX(IF((发射时间预测!$A:$A=TRIM(CLEAN(U6)))*(发射时间预测!$B:$B="太原"), ROW(发射时间预测!$A:$A))), 1), "太原")} -> 太原 | V2: {=HYPERLINK("#发射时间预测!" & ADDRESS(MAX(IF((发射时间预测!$A:$A=TRIM(CLEAN(V6)))*(发射时间预测!$B:$B="太原"), ROW(发射时间预测!$A:$A))), 1), "太原")} -> 太原 | W2: {=HYPERLINK("#发射时间预测!" & ADDRESS(MAX(IF((发射时间预测!$A:$A=TRIM(CLEAN(W6)))*(发射时间预测!$B:$B="文昌"), ROW(发射时间预测!$A:$A))), 1), "文昌")} -> 文昌 | X2: {=HYPERLINK("#发射时间预测!" & ADDRESS(MAX(IF((发射时间预测!$A:$A=TRIM(CLEAN(X6)))*(发射时间预测!$B:$B="文昌"), ROW(发射时间预测!$A:$A))), 1), "文昌")} -> 文昌 | Y2: {=HYPERLINK("#发射时间预测!" & ADDRESS(MAX(IF((发射时间预测!$A:$A=TRIM(CLEAN(Y6)))*(发射时间预测!$B:$B="文昌"), ROW(发射时间预测!$A:$A))), 1), "文昌")} -> 文昌 | Z2: {=HYPERLINK("#发射时间预测!" & ADDRESS(MAX(IF((发射时间预测!$A:$A=TRIM(CLEAN(Z6)))*(发射时间预测!$B:$B="文昌"), ROW(发射时间预测!$A:$A))), 1), "文昌")} -> 文昌 | AA2: {=HYPERLINK("#发射时间预测!" & ADDRESS(MAX(IF((发射时间预测!$A:$A=TRIM(CLEAN(AA$6)))*(发射时间预测!$B:$B="文昌"), ROW(发射时间预测!$A:$A))), 1), "文昌")} -> 文昌 | AB2: {=HYPERLINK("#发射时间预测!" & ADDRESS(MAX(IF((发射时间预测!$A:$A=TRIM(CLEAN(AB$6)))*(发射时间预测!$B:$B="文昌"), ROW(发射时间预测!$A:$A))), 1), "文昌")} -> 文昌 | AC2: {=HYPERLINK("#发射时间预测!" & ADDRESS(MAX(IF((发射时间预测!$A:$A=TRIM(CLEAN(AC$6)))*(发射时间预测!$B:$B="海南"), ROW(发射时间预测!$A:$A))), 1), "海南")} -> 海南 | AD2: {=HYPERLINK("#发射时间预测!" & ADDRESS(MAX(IF((发射时间预测!$A:$A=TRIM(CLEAN(AD6)))*(发射时间预测!$B:$B="酒泉"), ROW(发射时间预测!$A:$A))), 1), "酒泉")} -> 酒泉 | AE2: {=HYPERLINK("#发射时间预测!" & ADDRESS(MAX(IF((发射时间预测!$A:$A=TRIM(CLEAN(AE$6)))*(发射时间预测!$B:$B="黄海"), ROW(发射时间预测!$A:$A))), 1), "黄海")} -> 黄海 | AF2: {=HYPERLINK("#发射时间预测!" & ADDRESS(MAX(IF((发射时间预测!A:A="长征十二号")*(发射时间预测!B:B="海南"), ROW(发射时间预测!A:A))), 1), "海南")} -> 海南 | AG2: {=HYPERLINK("#发射时间预测!" & ADDRESS(MAX(IF((发射时间预测!$A:$A=TRIM(CLEAN(AG6)))*(发射时间预测!$B:$B="酒泉"), ROW(发射时间预测!$A:$A))), 1), "酒泉")} -> 酒泉 | AH2: {=HYPERLINK("#发射时间预测!" & ADDRESS(MAX(IF((发射时间预测!$A:$A=TRIM(CLEAN(AH6)))*(发射时间预测!$B:$B="酒泉"), ROW(发射时间预测!$A:$A))), 1), "酒泉")} -> 酒泉 | AI2: {=HYPERLINK("#发射时间预测!" & ADDRESS(MAX(IF((发射时间预测!$A:$A=TRIM(CLEAN(AI$6)))*(发射时间预测!$B:$B="黄海"), ROW(发射时间预测!$A:$A))), 1), "黄海")} -> 黄海 | AO2: {=HYPERLINK("#发射时间预测!" & ADDRESS(MAX(IF((发射时间预测!$A:$A=TRIM(CLEAN(AO6)))*(发射时间预测!$B:$B="酒泉"), ROW(发射时间预测!$A:$A))), 1), "酒泉")} -> 酒泉 | AP2: {=HYPERLINK("#发射时间预测!" & ADDRESS(MAX(IF((发射时间预测!$A:$A=TRIM(CLEAN(AP$6)))*(发射时间预测!$B:$B="酒泉"), ROW(发射时间预测!$A:$A))), 1), "酒泉")} -> 酒泉 | AR2: {=HYPERLINK("#发射时间预测!" & ADDRESS(MAX(IF((发射时间预测!A:A="朱雀二号")*(发射时间预测!B:B="酒泉"), ROW(发射时间预测!A:A))), 1), "酒泉")} -> 酒泉 | AS2: {=HYPERLINK("#发射时间预测!" & ADDRESS(MAX(IF((发射时间预测!$A:$A=TRIM(CLEAN(AS6)))*(发射时间预测!$B:$B="酒泉"), ROW(发射时间预测!$A:$A))), 1), "酒泉")} -> 酒泉 | AT2: {=HYPERLINK("#发射时间预测!" & ADDRESS(MAX(IF((发射时间预测!$A:$A=TRIM(CLEAN(AT6)))*(发射时间预测!$B:$B="酒泉"), ROW(发射时间预测!$A:$A))), 1), "酒泉")} -> 酒泉 | AV2: {=HYPERLINK("#发射时间预测!" & ADDRESS(MAX(IF((发射时间预测!$A:$A=TRIM(CLEAN(AV6)))*(发射时间预测!$B:$B="酒泉"), ROW(发射时间预测!$A:$A))), 1), "酒泉")} -> 酒泉 | AX2: {=HYPERLINK("#发射时间预测!" & ADDRESS(MAX(IF((发射时间预测!$A:$A=TRIM(CLEAN(AX$6)))*(发射时间预测!$B:$B="黄海"), ROW(发射时间预测!$A:$A))), 1), "黄海")} -> 黄海 | AY2: {=HYPERLINK("#发射时间预测!" & ADDRESS(MAX(IF((发射时间预测!$A:$A=TRIM(CLEAN(AY6)))*(发射时间预测!$B:$B="酒泉"), ROW(发射时间预测!$A:$A))), 1), "酒泉")} -> 酒泉 | AZ2: {=HYPERLINK("#发射时间预测!" & ADDRESS(MAX(IF((发射时间预测!$A:$A=TRIM(CLEAN(AZ$6)))*(发射时间预测!$B:$B="黄海"), ROW(发射时间预测!$A:$A))), 1), "黄海")} -> 黄海 | BA2: {=HYPERLINK("#发射时间预测!" & ADDRESS(MAX(IF((发射时间预测!$A:$A=TRIM(CLEAN(BA6)))*(发射时间预测!$B:$B="酒泉"), ROW(发射时间预测!$A:$A))), 1), "酒泉")} -> 酒泉 | BB2: {=HYPERLINK("#发射时间预测!" & ADDRESS(MAX(IF((发射时间预测!$A:$A=TRIM(CLEAN(BB6)))*(发射时间预测!$B:$B="酒泉"), ROW(发射时间预测!$A:$A))), 1), "酒泉")} -> 酒泉 | BC2: {=HYPERLINK("#发射时间预测!" & ADDRESS(MAX(IF((发射时间预测!$A:$A="力箭一号")*(发射时间预测!$B:$B="酒泉"), ROW(发射时间预测!$A:$A))), 1), "酒泉")} -> 酒泉 | BD2: {=HYPERLINK("#发射时间预测!" & ADDRESS(MAX(IF((发射时间预测!$A:$A="力箭二号")*(发射时间预测!$B:$B="酒泉"), ROW(发射时间预测!$A:$A))), 1), "酒泉")} -> 酒泉 | BE2: {=HYPERLINK("#发射时间预测!" & ADDRESS(MAX(IF((发射时间预测!$A:$A=TRIM(CLEAN(BE6)))*(发射时间预测!$B:$B="酒泉"), ROW(发射时间预测!$A:$A))), 1), "酒泉")} -> 酒泉 | BF2: {=HYPERLINK("#发射时间预测!" & ADDRESS(MAX(IF((发射时间预测!$A:$A=TRIM(CLEAN(BF6)))*(发射时间预测!$B:$B="酒泉"), ROW(发射时间预测!$A:$A))), 1), "酒泉")} -> 酒泉 | BG2: {=HYPERLINK("#发射时间预测!" & ADDRESS(MAX(IF((发射时间预测!$A:$A=TRIM(CLEAN(BG$6)))*(发射时间预测!$B:$B="黄海"), ROW(发射时间预测!$A:$A))), 1), "黄海")} -> 黄海 | BH2: {=HYPERLINK("#发射时间预测!" & ADDRESS(MAX(IF((发射时间预测!$A:$A=TRIM(CLEAN(BH6)))*(发射时间预测!$B:$B="酒泉"), ROW(发射时间预测!$A:$A))), 1), "酒泉")} -> 酒泉
G3: {=HYPERLINK("#发射时间预测!" & ADDRESS(MAX(IF((发射时间预测!$A:$A=TRIM(CLEAN(G6)))*(发射时间预测!$B:$B="西昌"), ROW(发射时间预测!$A:$A))), 1), "西昌")} -> 西昌 | H3: {=HYPERLINK("#发射时间预测!" & ADDRESS(MAX(IF((发射时间预测!$A:$A=TRIM(CLEAN(H6)))*(发射时间预测!$B:$B="西昌"), ROW(发射时间预测!$A:$A))), 1), "西昌")} -> 西昌 | P3: {=HYPERLINK("#发射时间预测!" & ADDRESS(MAX(IF((发射时间预测!$A:$A=TRIM(CLEAN(P6)))*(发射时间预测!$B:$B="西昌"), ROW(发射时间预测!$A:$A))), 1), "西昌")} -> 西昌 | Q3: {=HYPERLINK("#发射时间预测!" & ADDRESS(MAX(IF((发射时间预测!$A:$A=TRIM(CLEAN(Q$6)))*(发射时间预测!$B:$B="西昌"), ROW(发射时间预测!$A:$A))), 1), "西昌")} -> 西昌 | Y3: {=HYPERLINK("#发射时间预测!" & ADDRESS(MAX(IF((发射时间预测!$A:$A=TRIM(CLEAN(Y$6)))*(发射时间预测!$B:$B="海南"), ROW(发射时间预测!$A:$A))), 1), "海南")} -> 海南 | Z3: {=HYPERLINK("#发射时间预测!" & ADDRESS(MAX(IF((发射时间预测!$A:$A=TRIM(CLEAN(Z$6)))*(发射时间预测!$B:$B="海南"), ROW(发射时间预测!$A:$A))), 1), "海南")} -> 海南 | AD3: {=HYPERLINK("#发射时间预测!" & ADDRESS(MAX(IF((发射时间预测!$A:$A=TRIM(CLEAN(AD$6)))*(发射时间预测!$B:$B="西昌"), ROW(发射时间预测!$A:$A))), 1), "西昌")} -> 西昌 | AE3: {=HYPERLINK("#发射时间预测!" & ADDRESS(MAX(IF((发射时间预测!$A:$A=TRIM(CLEAN(AE$6)))*(发射时间预测!$B:$B="东海"), ROW(发射时间预测!$A:$A))), 1), "东海")} -> 东海 | AO3: {=HYPERLINK("#发射时间预测!" & ADDRESS(MAX(IF((发射时间预测!$A:$A=TRIM(CLEAN(AO6)))*(发射时间预测!$B:$B="西昌"), ROW(发射时间预测!$A:$A))), 1), "西昌")} -> 西昌 | AX3: {=HYPERLINK("#发射时间预测!" & ADDRESS(MAX(IF((发射时间预测!$A:$A=TRIM(CLEAN(AX$6)))*(发射时间预测!$B:$B="南海"), ROW(发射时间预测!$A:$A))), 1), "南海")} -> 南海
G4: {=HYPERLINK("#发射时间预测!" & ADDRESS(MAX(IF((发射时间预测!$A:$A=TRIM(CLEAN(G$6)))*(发射时间预测!$B:$B="太原"), ROW(发射时间预测!$A:$A))), 1), "太原")} -> 太原 | H4: {=HYPERLINK("#发射时间预测!" & ADDRESS(MAX(IF((发射时间预测!$A:$A=TRIM(CLEAN(H$6)))*(发射时间预测!$B:$B="太原"), ROW(发射时间预测!$A:$A))), 1), "太原")} -> 太原 | P4: {=HYPERLINK("#发射时间预测!" & ADDRESS(MAX(IF((发射时间预测!$A:$A=TRIM(CLEAN(P$6)))*(发射时间预测!$B:$B="太原"), ROW(发射时间预测!$A:$A))), 1), "太原")} -> 太原 | Q4: {=HYPERLINK("#发射时间预测!" & ADDRESS(MAX(IF((发射时间预测!$A:$A=TRIM(CLEAN(Q$6)))*(发射时间预测!$B:$B="太原"), ROW(发射时间预测!$A:$A))), 1), "太原")} -> 太原 | AE4: {=HYPERLINK("#发射时间预测!" & ADDRESS(MAX(IF((发射时间预测!$A:$A=TRIM(CLEAN(AE$6)))*(发射时间预测!$B:$B="南海"), ROW(发射时间预测!$A:$A))), 1), "南海")} -> 南海 | AO4: {=HYPERLINK("#发射时间预测!" & ADDRESS(MAX(IF((发射时间预测!$A:$A=TRIM(CLEAN(AO$6)))*(发射时间预测!$B:$B="太原"), ROW(发射时间预测!$A:$A))), 1), "太原")} -> 太原
A5: 年份 | B5: 总计 | C5: 长征 合计 | G5: =G9 -> 87 | H5: =H9 -> 105 | J5: =J9 -> 29 | M5: =SUM(L9:N9) -> 163 | P5: =SUM(O9:Q9) -> 118 | R5: =SUM(R9:S9) -> 18 | T5: =SUM(T9:V9) -> 41 | W5: =SUM(W9:X9) -> 27 | Y5: =Y9+Z9 -> 16 | AA5: =SUM(AA9:AC9) -> 0 | AD5: =SUM(AD9:AE9) -> 18 | AF5: =SUM(AF9:AI9) -> 8 | AJ5: 其他 合计 | AL5: =AL9+AM9 -> 4 | AR5: =SUM(AQ9:AT9) -> 10 | AV5: =AV9 -> 8 | AW5: =AW9+AX9 -> 12 | AY5: =SUM(AY9:BB9) -> 24 | BC5: =BC9+BD9 -> 15 | BE5: =BE9+BF9 -> 2 | BG5: =BG9 -> 2 | BH5: =BH9 -> 0
D6: 长征 一号 | E6: 长征 二号 | F6: 长征 二号甲 | G6: =HYPERLINK("..\htmls\长征二号丙运载火箭发射历史.html","长征"&CHAR(10)&"二号丙") -> 长征 二号丙 | H6: =HYPERLINK("..\htmls\长征二号丁运载火箭发射历史.html","长征"&CHAR(10)&"二号丁") -> 长征 二号丁 | I6: 长征 二号捆 | J6: 长征 二号己 | K6: 长征 三号 | L6: 长征 三号甲 | M6: 长征 三号乙 | N6: 长征 三号丙 | O6: 长征 四号甲 | P6: 长征 四号乙 | Q6: 长征 四号丙 | R6: 长征 五号 | S6: 长征 五号乙 | T6: 长征 六号 | U6: 长征 六号甲 | V6: 长征 六号丙 | W6: 长征 七号 | X6: 长征 七号甲 | Y6: 长征 八号 | Z6: 长征 八号甲 | AA6: 长征 十号 | AB6: 长征 十号甲 | AC6: 长征 十号乙 | AD6: 长征 十一号 | AE6: 长征 十一号海 | AF6: 长征 十二号 | AG6: 长征 十二号甲 | AH6: 长征 十二号乙 | AI6: 长征 十二号海 | AK6: 风暴 一号 | AL6: 开拓者 一号 | AM6: 开拓者 二号 | AN6: 快舟 一号 | AO6: 快舟 一号甲 | AP6: 快舟 十一号 | AQ6: 朱雀 一号 | AR6: 朱雀 二号 | AS6: 朱雀 二号Ｅ | AT6: 朱雀 三号 | AU6: OS-M | AV6: 双曲线 一号 | AW6: 捷龙 一号 | AX6: 捷龙 三号 | AY6: 谷神星 一号 | AZ6: 谷神星 一号海 | BA6: 谷神星 二号 | BB6: 智神星 一号 | BC6: 力箭 一号 | BD6: 力箭 二号 | BE6: 天龙 二号 | BF6: 天龙 三号 | BG6: 引力 一号 | BH6: 致航 一号
A7: 成功率 | B7: =IF(B9>0,B8/B9,"-") -> 0.94615385 | C7: =IF(C9>0,C8/C9,"-") -> 0.97103659 | D7: =D8/D9 -> 1 | E7: =E8/E9 -> 0 | F7: =F8/F9 -> 1 | G7: =G8/G9 -> 0.97701149 | H7: =H8/H9 -> 0.99047619 | I7: =I8/I9 -> 0.71428571 | J7: =J8/J9 -> 1 | K7: =IF(K9>0,K8/K9,"-") -> 0.76923077 | L7: =IF(L9>0,L8/L9,"-") -> 1 | M7: =IF(M9>0,M8/M9,"-") -> 0.95689655 | N7: =IF(N9>0,N8/N9,"-") -> 1 | O7: =IF(O9>0,O8/O9,"-") -> 1 | P7: =IF(P9>0,P8/P9,"-") -> 0.98245614 | Q7: =IF(Q9>0,Q8/Q9,"-") -> 0.96610169 | R7: =IF(R9>0,R8/R9,"-") -> 0.90909091 | ... AJ7: =IF(AJ9>0,AJ8/AJ9,"-") -> 0.81451613 | AK7: 0.5 | AL7: 0 | AM7: 1 | AN7: 1 | AO7: =IF(AO9>0,AO8/AO9,"-") -> 0.93333333 | AP7: =IF(AP9>0,AP8/AP9,"-") -> 0.83333333 | AQ7: =IF(AQ9>0,AQ8/AQ9,"-") -> 0 | AR7: =IF(AR9>0,AR8/AR9,"-") -> 0.66666667 | AS7: =IF(AS9>0,AS8/AS9,"-") -> 0.8 | AT7: =IF(AT9>0,AT8/AT9,"-") -> 1 | AU7: =IF(AU9>0,AU8/AU9,"-") -> 0 | AV7: =IF(AV9>0,AV8/AV9,"-") -> 0.5 | ... BH7: =IF(BH9>0,BH8/BH9,"-") -> -
A8: 成功数 | B8: =C8+AJ8 -> 738 | C8: =SUM(D8:AH8) -> 637 | D8: =COUNTIFS(发射纪录!$B:$B,"<>-",发射纪录!$N:$N,"=成功",发射纪录!$D:$D,"="&CLEAN(火箭年間統計!D$6)) -> 2 | E8: =COUNTIFS(发射纪录!$B:$B,"<>-",发射纪录!$N:$N,"=成功",发射纪录!$D:$D,"="&CLEAN(火箭年間統計!E$6)) -> 0 | F8: =COUNTIFS(发射纪录!$B:$B,"<>-",发射纪录!$N:$N,"=成功",发射纪录!$D:$D,"="&CLEAN(火箭年間統計!F$6)) -> 3 | G8: =COUNTIFS(发射纪录!$B:$B,"<>-",发射纪录!$N:$N,"=成功",发射纪录!$D:$D,"="&CLEAN(G$6)) -> 85 | H8: =COUNTIFS(发射纪录!$B:$B,"<>-",发射纪录!$N:$N,"=成功",发射纪录!$D:$D,"="&CLEAN(H$6)) -> 104 | I8: =COUNTIFS(发射纪录!$B:$B,"<>-",发射纪录!$N:$N,"=成功",发射纪录!$D:$D,"="&CLEAN(I$6)) -> 5 | J8: =COUNTIFS(发射纪录!$B:$B,"<>-",发射纪录!$N:$N,"=成功",发射纪录!$D:$D,"="&CLEAN(J$6)) -> 29 | K8: =COUNTIFS(发射纪录!$B:$B,"<>-",发射纪录!$N:$N,"=成功",发射纪录!$D:$D,"="&CLEAN(K$6)) -> 10 | L8: =COUNTIFS(发射纪录!$B:$B,"<>-",发射纪录!$N:$N,"=成功",发射纪录!$D:$D,"="&CLEAN(L$6)) -> 27 | M8: =COUNTIFS(发射纪录!$B:$B,"<>-",发射纪录!$N:$N,"=成功",发射纪录!$D:$D,"="&CLEAN(M$6)) -> 111 | N8: =COUNTIFS(发射纪录!$B:$B,"<>-",发射纪录!$N:$N,"=成功",发射纪录!$D:$D,"="&CLEAN(N$6)) -> 20 | ... AI8: =COUNTIFS(发射纪录!$B:$B,"<>-",发射纪录!$N:$N,"=成功",发射纪录!$D:$D,"="&CLEAN(AI$6)) -> 0 | AJ8: =SUM(AK8:BH8) -> 101 | AK8: 4 | AL8: 0 | AM8: 1 | AN8: 2 | AO8: =COUNTIFS(发射纪录!$C:$C,"<>-",发射纪录!$N:$N,"=成功",发射纪录!$D:$D,"="&CLEAN(AO$6)) -> 28 | AP8: =COUNTIFS(发射纪录!$C:$C,"<>-",发射纪录!$N:$N,"=成功",发射纪录!$D:$D,"="&CLEAN(AP$6)) -> 5 | AQ8: =COUNTIFS(发射纪录!$C:$C,"<>-",发射纪录!$N:$N,"=成功",发射纪录!$D:$D,"="&CLEAN(AQ$6)) -> 0 | AR8: =COUNTIFS(发射纪录!$C:$C,"<>-",发射纪录!$N:$N,"=成功",发射纪录!$D:$D,"="&CLEAN(AR$6)) -> 2 | AS8: =COUNTIFS(发射纪录!$C:$C,"<>-",发射纪录!$N:$N,"=成功",发射纪录!$D:$D,"="&CLEAN(AS$6)) -> 4 | AT8: =COUNTIFS(发射纪录!$C:$C,"<>-",发射纪录!$N:$N,"=成功",发射纪录!$D:$D,"="&CLEAN(AT$6)) -> 1 | AU8: =COUNTIFS(发射纪录!$C:$C,"<>-",发射纪录!$N:$N,"=成功",发射纪录!$D:$D,"="&CLEAN(AU$6)) -> 0 | AV8: =COUNTIFS(发射纪录!$C:$C,"<>-",发射纪录!$N:$N,"=成功",发射纪录!$D:$D,"="&CLEAN(AV$6)) -> 4 | ... BH8: =COUNTIFS(发射纪录!$C:$C,"<>-",发射纪录!$N:$N,"=成功",发射纪录!$D:$D,"="&CLEAN(BH$6)) -> 0
A9: 发射数 | B9: =C9+AJ9 -> 780 | C9: =SUM(D9:AH9) -> 656 | D9: =SUM(D10:D64) -> 2 | E9: =SUM(E10:E64) -> 1 | F9: =SUM(F10:F64) -> 3 | G9: =COUNTIFS(发射纪录!$B:$B,"<>-",发射纪录!$N:$N,"<>",发射纪录!$D:$D,"="&CLEAN(G$6)) -> 87 | H9: =COUNTIFS(发射纪录!$B:$B,"<>-",发射纪录!$N:$N,"<>",发射纪录!$D:$D,"="&CLEAN(H$6)) -> 105 | I9: =COUNTIFS(发射纪录!$B:$B,"<>-",发射纪录!$N:$N,"<>",发射纪录!$D:$D,"="&CLEAN(I$6)) -> 7 | J9: =COUNTIFS(发射纪录!$B:$B,"<>-",发射纪录!$N:$N,"<>",发射纪录!$D:$D,"="&CLEAN(J$6)) -> 29 | K9: =COUNTIFS(发射纪录!$B:$B,"<>-",发射纪录!$N:$N,"<>",发射纪录!$D:$D,"="&CLEAN(K$6)) -> 13 | L9: =COUNTIFS(发射纪录!$B:$B,"<>-",发射纪录!$N:$N,"<>",发射纪录!$D:$D,"="&CLEAN(L$6)) -> 27 | M9: =COUNTIFS(发射纪录!$B:$B,"<>-",发射纪录!$N:$N,"<>",发射纪录!$D:$D,"="&CLEAN(M$6)) -> 116 | N9: =COUNTIFS(发射纪录!$B:$B,"<>-",发射纪录!$N:$N,"<>",发射纪录!$D:$D,"="&CLEAN(N$6)) -> 20 | ... AI9: =COUNTIFS(发射纪录!$B:$B,"<>-",发射纪录!$N:$N,"<>",发射纪录!$D:$D,"="&CLEAN(AI$6)) -> 0 | AJ9: =SUM(AK9:BH9) -> 124 | AK9: 8 | AL9: 3 | AM9: 1 | AN9: 2 | AO9: =COUNTIFS(发射纪录!$C:$C,"<>-",发射纪录!$N:$N,"<>",发射纪录!$D:$D,"="&CLEAN(AO$6)) -> 30 | AP9: =COUNTIFS(发射纪录!$C:$C,"<>-",发射纪录!$N:$N,"<>",发射纪录!$D:$D,"="&CLEAN(AP$6)) -> 6 | AQ9: =COUNTIFS(发射纪录!$C:$C,"<>-",发射纪录!$N:$N,"<>",发射纪录!$D:$D,"="&CLEAN(AQ$6)) -> 1 | AR9: =COUNTIFS(发射纪录!$C:$C,"<>-",发射纪录!$N:$N,"<>",发射纪录!$D:$D,"="&CLEAN(AR$6)) -> 3 | AS9: =COUNTIFS(发射纪录!$C:$C,"<>-",发射纪录!$N:$N,"<>",发射纪录!$D:$D,"="&CLEAN(AS$6)) -> 5 | AT9: =COUNTIFS(发射纪录!$C:$C,"<>-",发射纪录!$N:$N,"<>",发射纪录!$D:$D,"="&CLEAN(AT$6)) -> 1 | AU9: =COUNTIFS(发射纪录!$C:$C,"<>-",发射纪录!$N:$N,"<>",发射纪录!$D:$D,"="&CLEAN(AU$6)) -> 1 | AV9: =COUNTIFS(发射纪录!$C:$C,"<>-",发射纪录!$N:$N,"<>",发射纪录!$D:$D,"="&CLEAN(AV$6)) -> 8 | ... BH9: =COUNTIFS(发射纪录!$C:$C,"<>-",发射纪录!$N:$N,"<>",发射纪录!$D:$D,"="&CLEAN(BH$6)) -> 0
A10: 25569 | B10: 1 | C10: 1 | D10: =COUNTIFS(发射纪录!$B:$B,"<>-",发射纪录!$G:$G,">="&DATE(YEAR($A10),1,1),发射纪录!$G:$G,"<="&DATE(YEAR($A10),12,31),发射纪录!$N:$N,"<>",发射纪录!$D:$D,"="&CLEAN(火箭年間統計!D$6)) -> 1 | E10: =COUNTIFS(发射纪录!$B:$B,"<>-",发射纪录!$G:$G,">="&DATE(YEAR($A10),1,1),发射纪录!$G:$G,"<="&DATE(YEAR($A10),12,31),发射纪录!$N:$N,"<>",发射纪录!$D:$D,"="&CLEAN(火箭年間統計!E$6)) -> 0 | F10: =COUNTIFS(发射纪录!$B:$B,"<>-",发射纪录!$G:$G,">="&DATE(YEAR($A10),1,1),发射纪录!$G:$G,"<="&DATE(YEAR($A10),12,31),发射纪录!$N:$N,"<>",发射纪录!$D:$D,"="&CLEAN(火箭年間統計!F$6)) -> 0 | G10: 0 | H10: 0 | I10: 0 | J10: 0 | K10: 0 | L10: 0 | M10: 0 | N10: 0 | O10: 0 | P10: 0 | Q10: 0 | R10: 0 | S10: 0 | T10: 0 | U10: 0 | V10: 0 | W10: 0 | X10: 0 | Y10: 0 | Z10: 0 | AA10: 0 | AB10: 0 | AC10: 0 | AD10: 0 | AE10: 0 | AF10: 0 | AG10: 0 | AH10: 0 | AI10: 0 | AJ10: 0 | AK10: 0 | AL10: 0 | AM10: 0 | AN10: 0 | AO10: 0 | AP10: 0 | AQ10: 0 | AR10: 0 | AS10: 0 | AT10: 0 | AU10: 0 | AV10: 0 | AW10: 0 | AX10: 0 | AY10: 0 | AZ10: 0 | BA10: 0 | BB10: 0 | BC10: 0 | BD10: 0 | BE10: 0 | BF10: 0 | BG10: 0 | BH10: 0
A11: 25934 | B11: 1 | C11: 1 | D11: =COUNTIFS(发射纪录!$B:$B,"<>-",发射纪录!$G:$G,">="&DATE(YEAR($A11),1,1),发射纪录!$G:$G,"<="&DATE(YEAR($A11),12,31),发射纪录!$N:$N,"<>",发射纪录!$D:$D,"="&CLEAN(火箭年間統計!D$6)) -> 1 | E11: =COUNTIFS(发射纪录!$B:$B,"<>-",发射纪录!$G:$G,">="&DATE(YEAR($A11),1,1),发射纪录!$G:$G,"<="&DATE(YEAR($A11),12,31),发射纪录!$N:$N,"<>",发射纪录!$D:$D,"="&CLEAN(火箭年間統計!E$6)) -> 0 | F11: =COUNTIFS(发射纪录!$B:$B,"<>-",发射纪录!$G:$G,">="&DATE(YEAR($A11),1,1),发射纪录!$G:$G,"<="&DATE(YEAR($A11),12,31),发射纪录!$N:$N,"<>",发射纪录!$D:$D,"="&CLEAN(火箭年間統計!F$6)) -> 0 | G11: 0 | H11: 0 | I11: 0 | J11: 0 | K11: 0 | L11: 0 | M11: 0 | N11: 0 | O11: 0 | P11: 0 | Q11: 0 | R11: 0 | S11: 0 | T11: 0 | U11: 0 | V11: 0 | W11: 0 | X11: 0 | Y11: 0 | Z11: 0 | AA11: 0 | AB11: 0 | AC11: 0 | AD11: 0 | AE11: 0 | AF11: 0 | AG11: 0 | AH11: 0 | AI11: 0 | AJ11: 0 | AK11: 0 | AL11: 0 | AM11: 0 | AN11: 0 | AO11: 0 | AP11: 0 | AQ11: 0 | AR11: 0 | AS11: 0 | AT11: 0 | AU11: 0 | AV11: 0 | AW11: 0 | AX11: 0 | AY11: 0 | AZ11: 0 | BA11: 0 | BB11: 0 | BC11: 0 | BD11: 0 | BE11: 0 | BF11: 0 | BG11: 0 | BH11: 0
A12: 26299 | B12: 0 | C12: 0 | D12: =COUNTIFS(发射纪录!$B:$B,"<>-",发射纪录!$G:$G,">="&DATE(YEAR($A12),1,1),发射纪录!$G:$G,"<="&DATE(YEAR($A12),12,31),发射纪录!$N:$N,"<>",发射纪录!$D:$D,"="&CLEAN(火箭年間統計!D$6)) -> 0 | E12: =COUNTIFS(发射纪录!$B:$B,"<>-",发射纪录!$G:$G,">="&DATE(YEAR($A12),1,1),发射纪录!$G:$G,"<="&DATE(YEAR($A12),12,31),发射纪录!$N:$N,"<>",发射纪录!$D:$D,"="&CLEAN(火箭年間統計!E$6)) -> 0 | F12: =COUNTIFS(发射纪录!$B:$B,"<>-",发射纪录!$G:$G,">="&DATE(YEAR($A12),1,1),发射纪录!$G:$G,"<="&DATE(YEAR($A12),12,31),发射纪录!$N:$N,"<>",发射纪录!$D:$D,"="&CLEAN(火箭年間統計!F$6)) -> 0 | G12: 0 | H12: 0 | I12: 0 | J12: 0 | K12: 0 | L12: 0 | M12: 0 | N12: 0 | O12: 0 | P12: 0 | Q12: 0 | R12: 0 | S12: 0 | T12: 0 | U12: 0 | V12: 0 | W12: 0 | X12: 0 | Y12: 0 | Z12: 0 | AA12: 0 | AB12: 0 | AC12: 0 | AD12: 0 | AE12: 0 | AF12: 0 | AG12: 0 | AH12: 0 | AI12: 0 | AJ12: 0 | AK12: 0 | AL12: 0 | AM12: 0 | AN12: 0 | AO12: 0 | AP12: 0 | AQ12: 0 | AR12: 0 | AS12: 0 | AT12: 0 | AU12: 0 | AV12: 0 | AW12: 0 | AX12: 0 | AY12: 0 | AZ12: 0 | BA12: 0 | BB12: 0 | BC12: 0 | BD12: 0 | BE12: 0 | BF12: 0 | BG12: 0 | BH12: 0
A13: 26665 | B13: 1 | C13: 0 | D13: =COUNTIFS(发射纪录!$B:$B,"<>-",发射纪录!$G:$G,">="&DATE(YEAR($A13),1,1),发射纪录!$G:$G,"<="&DATE(YEAR($A13),12,31),发射纪录!$N:$N,"<>",发射纪录!$D:$D,"="&CLEAN(火箭年間統計!D$6)) -> 0 | E13: =COUNTIFS(发射纪录!$B:$B,"<>-",发射纪录!$G:$G,">="&DATE(YEAR($A13),1,1),发射纪录!$G:$G,"<="&DATE(YEAR($A13),12,31),发射纪录!$N:$N,"<>",发射纪录!$D:$D,"="&CLEAN(火箭年間統計!E$6)) -> 0 | F13: =COUNTIFS(发射纪录!$B:$B,"<>-",发射纪录!$G:$G,">="&DATE(YEAR($A13),1,1),发射纪录!$G:$G,"<="&DATE(YEAR($A13),12,31),发射纪录!$N:$N,"<>",发射纪录!$D:$D,"="&CLEAN(火箭年間統計!F$6)) -> 0 | G13: 0 | H13: 0 | I13: 0 | J13: 0 | K13: 0 | L13: 0 | M13: 0 | N13: 0 | O13: 0 | P13: 0 | Q13: 0 | R13: 0 | S13: 0 | T13: 0 | U13: 0 | V13: 0 | W13: 0 | X13: 0 | Y13: 0 | Z13: 0 | AA13: 0 | AB13: 0 | AC13: 0 | AD13: 0 | AE13: 0 | AF13: 0 | AG13: 0 | AH13: 0 | AI13: 0 | AJ13: 1 | AK13: 1 | AL13: 0 | AM13: 0 | AN13: 0 | AO13: 0 | AP13: 0 | AQ13: 0 | AR13: 0 | AS13: 0 | AT13: 0 | AU13: 0 | AV13: 0 | AW13: 0 | AX13: 0 | AY13: 0 | AZ13: 0 | BA13: 0 | BB13: 0 | BC13: 0 | BD13: 0 | BE13: 0 | BF13: 0 | BG13: 0 | BH13: 0
A14: 27030 | B14: 2 | C14: 1 | D14: =COUNTIFS(发射纪录!$B:$B,"<>-",发射纪录!$G:$G,">="&DATE(YEAR($A14),1,1),发射纪录!$G:$G,"<="&DATE(YEAR($A14),12,31),发射纪录!$N:$N,"<>",发射纪录!$D:$D,"="&CLEAN(火箭年間統計!D$6)) -> 0 | E14: =COUNTIFS(发射纪录!$B:$B,"<>-",发射纪录!$G:$G,">="&DATE(YEAR($A14),1,1),发射纪录!$G:$G,"<="&DATE(YEAR($A14),12,31),发射纪录!$N:$N,"<>",发射纪录!$D:$D,"="&CLEAN(火箭年間統計!E$6)) -> 1 | F14: =COUNTIFS(发射纪录!$B:$B,"<>-",发射纪录!$G:$G,">="&DATE(YEAR($A14),1,1),发射纪录!$G:$G,"<="&DATE(YEAR($A14),12,31),发射纪录!$N:$N,"<>",发射纪录!$D:$D,"="&CLEAN(火箭年間統計!F$6)) -> 0 | G14: 0 | H14: 0 | I14: 0 | J14: 0 | K14: 0 | L14: 0 | M14: 0 | N14: 0 | O14: 0 | P14: 0 | Q14: 0 | R14: 0 | S14: 0 | T14: 0 | U14: 0 | V14: 0 | W14: 0 | X14: 0 | Y14: 0 | Z14: 0 | AA14: 0 | AB14: 0 | AC14: 0 | AD14: 0 | AE14: 0 | AF14: 0 | AG14: 0 | AH14: 0 | AI14: 0 | AJ14: 1 | AK14: 1 | AL14: 0 | AM14: 0 | AN14: 0 | AO14: 0 | AP14: 0 | AQ14: 0 | AR14: 0 | AS14: 0 | AT14: 0 | AU14: 0 | AV14: 0 | AW14: 0 | AX14: 0 | AY14: 0 | AZ14: 0 | BA14: 0 | BB14: 0 | BC14: 0 | BD14: 0 | BE14: 0 | BF14: 0 | BG14: 0 | BH14: 0
A15: 27395 | B15: 3 | C15: 1 | D15: =COUNTIFS(发射纪录!$B:$B,"<>-",发射纪录!$G:$G,">="&DATE(YEAR($A15),1,1),发射纪录!$G:$G,"<="&DATE(YEAR($A15),12,31),发射纪录!$N:$N,"<>",发射纪录!$D:$D,"="&CLEAN(火箭年間統計!D$6)) -> 0 | E15: =COUNTIFS(发射纪录!$B:$B,"<>-",发射纪录!$G:$G,">="&DATE(YEAR($A15),1,1),发射纪录!$G:$G,"<="&DATE(YEAR($A15),12,31),发射纪录!$N:$N,"<>",发射纪录!$D:$D,"="&CLEAN(火箭年間統計!E$6)) -> 0 | F15: =COUNTIFS(发射纪录!$B:$B,"<>-",发射纪录!$G:$G,">="&DATE(YEAR($A15),1,1),发射纪录!$G:$G,"<="&DATE(YEAR($A15),12,31),发射纪录!$N:$N,"<>",发射纪录!$D:$D,"="&CLEAN(火箭年間統計!F$6)) -> 1 | G15: 0 | H15: 0 | I15: 0 | J15: 0 | K15: 0 | L15: 0 | M15: 0 | N15: 0 | O15: 0 | P15: 0 | Q15: 0 | R15: 0 | S15: 0 | T15: 0 | U15: 0 | V15: 0 | W15: 0 | X15: 0 | Y15: 0 | Z15: 0 | AA15: 0 | AB15: 0 | AC15: 0 | AD15: 0 | AE15: 0 | AF15: 0 | AG15: 0 | AH15: 0 | AI15: 0 | AJ15: 2 | AK15: 2 | AL15: 0 | AM15: 0 | AN15: 0 | AO15: 0 | AP15: 0 | AQ15: 0 | AR15: 0 | AS15: 0 | AT15: 0 | AU15: 0 | AV15: 0 | AW15: 0 | AX15: 0 | AY15: 0 | AZ15: 0 | BA15: 0 | BB15: 0 | BC15: 0 | BD15: 0 | BE15: 0 | BF15: 0 | BG15: 0 | BH15: 0
A16: 27760 | B16: 3 | C16: 1 | D16: =COUNTIFS(发射纪录!$B:$B,"<>-",发射纪录!$G:$G,">="&DATE(YEAR($A16),1,1),发射纪录!$G:$G,"<="&DATE(YEAR($A16),12,31),发射纪录!$N:$N,"<>",发射纪录!$D:$D,"="&CLEAN(火箭年間統計!D$6)) -> 0 | E16: =COUNTIFS(发射纪录!$B:$B,"<>-",发射纪录!$G:$G,">="&DATE(YEAR($A16),1,1),发射纪录!$G:$G,"<="&DATE(YEAR($A16),12,31),发射纪录!$N:$N,"<>",发射纪录!$D:$D,"="&CLEAN(火箭年間統計!E$6)) -> 0 | F16: =COUNTIFS(发射纪录!$B:$B,"<>-",发射纪录!$G:$G,">="&DATE(YEAR($A16),1,1),发射纪录!$G:$G,"<="&DATE(YEAR($A16),12,31),发射纪录!$N:$N,"<>",发射纪录!$D:$D,"="&CLEAN(火箭年間統計!F$6)) -> 1 | G16: 0 | H16: 0 | I16: 0 | J16: 0 | K16: 0 | L16: 0 | M16: 0 | N16: 0 | O16: 0 | P16: 0 | Q16: 0 | R16: 0 | S16: 0 | T16: 0 | U16: 0 | V16: 0 | W16: 0 | X16: 0 | Y16: 0 | Z16: 0 | AA16: 0 | AB16: 0 | AC16: 0 | AD16: 0 | AE16: 0 | AF16: 0 | AG16: 0 | AH16: 0 | AI16: 0 | AJ16: 2 | AK16: 2 | AL16: 0 | AM16: 0 | AN16: 0 | AO16: 0 | AP16: 0 | AQ16: 0 | AR16: 0 | AS16: 0 | AT16: 0 | AU16: 0 | AV16: 0 | AW16: 0 | AX16: 0 | AY16: 0 | AZ16: 0 | BA16: 0 | BB16: 0 | BC16: 0 | BD16: 0 | BE16: 0 | BF16: 0 | BG16: 0 | BH16: 0
A17: 28126 | B17: 0 | C17: 0 | D17: =COUNTIFS(发射纪录!$B:$B,"<>-",发射纪录!$G:$G,">="&DATE(YEAR($A17),1,1),发射纪录!$G:$G,"<="&DATE(YEAR($A17),12,31),发射纪录!$N:$N,"<>",发射纪录!$D:$D,"="&CLEAN(火箭年間統計!D$6)) -> 0 | E17: =COUNTIFS(发射纪录!$B:$B,"<>-",发射纪录!$G:$G,">="&DATE(YEAR($A17),1,1),发射纪录!$G:$G,"<="&DATE(YEAR($A17),12,31),发射纪录!$N:$N,"<>",发射纪录!$D:$D,"="&CLEAN(火箭年間統計!E$6)) -> 0 | F17: =COUNTIFS(发射纪录!$B:$B,"<>-",发射纪录!$G:$G,">="&DATE(YEAR($A17),1,1),发射纪录!$G:$G,"<="&DATE(YEAR($A17),12,31),发射纪录!$N:$N,"<>",发射纪录!$D:$D,"="&CLEAN(火箭年間統計!F$6)) -> 0 | G17: 0 | H17: 0 | I17: 0 | J17: 0 | K17: 0 | L17: 0 | M17: 0 | N17: 0 | O17: 0 | P17: 0 | Q17: 0 | R17: 0 | S17: 0 | T17: 0 | U17: 0 | V17: 0 | W17: 0 | X17: 0 | Y17: 0 | Z17: 0 | AA17: 0 | AB17: 0 | AC17: 0 | AD17: 0 | AE17: 0 | AF17: 0 | AG17: 0 | AH17: 0 | AI17: 0 | AJ17: 0 | AK17: 0 | AL17: 0 | AM17: 0 | AN17: 0 | AO17: 0 | AP17: 0 | AQ17: 0 | AR17: 0 | AS17: 0 | AT17: 0 | AU17: 0 | AV17: 0 | AW17: 0 | AX17: 0 | AY17: 0 | AZ17: 0 | BA17: 0 | BB17: 0 | BC17: 0 | BD17: 0 | BE17: 0 | BF17: 0 | BG17: 0 | BH17: 0
A18: 28491 | B18: 1 | C18: 1 | D18: =COUNTIFS(发射纪录!$B:$B,"<>-",发射纪录!$G:$G,">="&DATE(YEAR($A18),1,1),发射纪录!$G:$G,"<="&DATE(YEAR($A18),12,31),发射纪录!$N:$N,"<>",发射纪录!$D:$D,"="&CLEAN(火箭年間統計!D$6)) -> 0 | E18: =COUNTIFS(发射纪录!$B:$B,"<>-",发射纪录!$G:$G,">="&DATE(YEAR($A18),1,1),发射纪录!$G:$G,"<="&DATE(YEAR($A18),12,31),发射纪录!$N:$N,"<>",发射纪录!$D:$D,"="&CLEAN(火箭年間統計!E$6)) -> 0 | F18: =COUNTIFS(发射纪录!$B:$B,"<>-",发射纪录!$G:$G,">="&DATE(YEAR($A18),1,1),发射纪录!$G:$G,"<="&DATE(YEAR($A18),12,31),发射纪录!$N:$N,"<>",发射纪录!$D:$D,"="&CLEAN(火箭年間統計!F$6)) -> 1 | G18: 0 | H18: 0 | I18: 0 | J18: 0 | K18: 0 | L18: 0 | M18: 0 | N18: 0 | O18: 0 | P18: 0 | Q18: 0 | R18: 0 | S18: 0 | T18: 0 | U18: 0 | V18: 0 | W18: 0 | X18: 0 | Y18: 0 | Z18: 0 | AA18: 0 | AB18: 0 | AC18: 0 | AD18: 0 | AE18: 0 | AF18: 0 | AG18: 0 | AH18: 0 | AI18: 0 | AJ18: 0 | AK18: 0 | AL18: 0 | AM18: 0 | AN18: 0 | AO18: 0 | AP18: 0 | AQ18: 0 | AR18: 0 | AS18: 0 | AT18: 0 | AU18: 0 | AV18: 0 | AW18: 0 | AX18: 0 | AY18: 0 | AZ18: 0 | BA18: 0 | BB18: 0 | BC18: 0 | BD18: 0 | BE18: 0 | BF18: 0 | BG18: 0 | BH18: 0
A19: 28856 | B19: 1 | C19: 0 | D19: =COUNTIFS(发射纪录!$B:$B,"<>-",发射纪录!$G:$G,">="&DATE(YEAR($A19),1,1),发射纪录!$G:$G,"<="&DATE(YEAR($A19),12,31),发射纪录!$N:$N,"<>",发射纪录!$D:$D,"="&CLEAN(火箭年間統計!D$6)) -> 0 | E19: =COUNTIFS(发射纪录!$B:$B,"<>-",发射纪录!$G:$G,">="&DATE(YEAR($A19),1,1),发射纪录!$G:$G,"<="&DATE(YEAR($A19),12,31),发射纪录!$N:$N,"<>",发射纪录!$D:$D,"="&CLEAN(火箭年間統計!E$6)) -> 0 | F19: =COUNTIFS(发射纪录!$B:$B,"<>-",发射纪录!$G:$G,">="&DATE(YEAR($A19),1,1),发射纪录!$G:$G,"<="&DATE(YEAR($A19),12,31),发射纪录!$N:$N,"<>",发射纪录!$D:$D,"="&CLEAN(火箭年間統計!F$6)) -> 0 | G19: 0 | H19: 0 | I19: 0 | J19: 0 | K19: 0 | L19: 0 | M19: 0 | N19: 0 | O19: 0 | P19: 0 | Q19: 0 | R19: 0 | S19: 0 | T19: 0 | U19: 0 | V19: 0 | W19: 0 | X19: 0 | Y19: 0 | Z19: 0 | AA19: 0 | AB19: 0 | AC19: 0 | AD19: 0 | AE19: 0 | AF19: 0 | AG19: 0 | AH19: 0 | AI19: 0 | AJ19: 1 | AK19: 1 | AL19: 0 | AM19: 0 | AN19: 0 | AO19: 0 | AP19: 0 | AQ19: 0 | AR19: 0 | AS19: 0 | AT19: 0 | AU19: 0 | AV19: 0 | AW19: 0 | AX19: 0 | AY19: 0 | AZ19: 0 | BA19: 0 | BB19: 0 | BC19: 0 | BD19: 0 | BE19: 0 | BF19: 0 | BG19: 0 | BH19: 0
A20: 29221 | B20: 0 | C20: 0 | D20: =COUNTIFS(发射纪录!$B:$B,"<>-",发射纪录!$G:$G,">="&DATE(YEAR($A20),1,1),发射纪录!$G:$G,"<="&DATE(YEAR($A20),12,31),发射纪录!$N:$N,"<>",发射纪录!$D:$D,"="&CLEAN(火箭年間統計!D$6)) -> 0 | E20: =COUNTIFS(发射纪录!$B:$B,"<>-",发射纪录!$G:$G,">="&DATE(YEAR($A20),1,1),发射纪录!$G:$G,"<="&DATE(YEAR($A20),12,31),发射纪录!$N:$N,"<>",发射纪录!$D:$D,"="&CLEAN(火箭年間統計!E$6)) -> 0 | F20: =COUNTIFS(发射纪录!$B:$B,"<>-",发射纪录!$G:$G,">="&DATE(YEAR($A20),1,1),发射纪录!$G:$G,"<="&DATE(YEAR($A20),12,31),发射纪录!$N:$N,"<>",发射纪录!$D:$D,"="&CLEAN(火箭年間統計!F$6)) -> 0 | G20: 0 | H20: 0 | I20: 0 | J20: 0 | K20: 0 | L20: 0 | M20: 0 | N20: 0 | O20: 0 | P20: 0 | Q20: 0 | R20: 0 | S20: 0 | T20: 0 | U20: 0 | V20: 0 | W20: 0 | X20: 0 | Y20: 0 | Z20: 0 | AA20: 0 | AB20: 0 | AC20: 0 | AD20: 0 | AE20: 0 | AF20: 0 | AG20: 0 | AH20: 0 | AI20: 0 | AJ20: 0 | AK20: 0 | AL20: 0 | AM20: 0 | AN20: 0 | AO20: 0 | AP20: 0 | AQ20: 0 | AR20: 0 | AS20: 0 | AT20: 0 | AU20: 0 | AV20: 0 | AW20: 0 | AX20: 0 | AY20: 0 | AZ20: 0 | BA20: 0 | BB20: 0 | BC20: 0 | BD20: 0 | BE20: 0 | BF20: 0 | BG20: 0 | BH20: 0
A21: 29587 | B21: 1 | C21: 0 | D21: =COUNTIFS(发射纪录!$B:$B,"<>-",发射纪录!$G:$G,">="&DATE(YEAR($A21),1,1),发射纪录!$G:$G,"<="&DATE(YEAR($A21),12,31),发射纪录!$N:$N,"<>",发射纪录!$D:$D,"="&CLEAN(火箭年間統計!D$6)) -> 0 | E21: =COUNTIFS(发射纪录!$B:$B,"<>-",发射纪录!$G:$G,">="&DATE(YEAR($A21),1,1),发射纪录!$G:$G,"<="&DATE(YEAR($A21),12,31),发射纪录!$N:$N,"<>",发射纪录!$D:$D,"="&CLEAN(火箭年間統計!E$6)) -> 0 | F21: =COUNTIFS(发射纪录!$B:$B,"<>-",发射纪录!$G:$G,">="&DATE(YEAR($A21),1,1),发射纪录!$G:$G,"<="&DATE(YEAR($A21),12,31),发射纪录!$N:$N,"<>",发射纪录!$D:$D,"="&CLEAN(火箭年間統計!F$6)) -> 0 | G21: 0 | H21: 0 | I21: 0 | J21: 0 | K21: 0 | L21: 0 | M21: 0 | N21: 0 | O21: 0 | P21: 0 | Q21: 0 | R21: 0 | S21: 0 | T21: 0 | U21: 0 | V21: 0 | W21: 0 | X21: 0 | Y21: 0 | Z21: 0 | AA21: 0 | AB21: 0 | AC21: 0 | AD21: 0 | AE21: 0 | AF21: 0 | AG21: 0 | AH21: 0 | AI21: 0 | AJ21: 1 | AK21: 1 | AL21: 0 | AM21: 0 | AN21: 0 | AO21: 0 | AP21: 0 | AQ21: 0 | AR21: 0 | AS21: 0 | AT21: 0 | AU21: 0 | AV21: 0 | AW21: 0 | AX21: 0 | AY21: 0 | AZ21: 0 | BA21: 0 | BB21: 0 | BC21: 0 | BD21: 0 | BE21: 0 | BF21: 0 | BG21: 0 | BH21: 0
... A50: 40179 | B50: 15 | C50: 15 | D50: =COUNTIFS(发射纪录!$B:$B,"<>-",发射纪录!$G:$G,">="&DATE(YEAR($A50),1,1),发射纪录!$G:$G,"<="&DATE(YEAR($A50),12,31),发射纪录!$N:$N,"<>",发射纪录!$D:$D,"="&CLEAN(火箭年間統計!D$6)) -> 0 | E50: =COUNTIFS(发射纪录!$B:$B,"<>-",发射纪录!$G:$G,">="&DATE(YEAR($A50),1,1),发射纪录!$G:$G,"<="&DATE(YEAR($A50),12,31),发射纪录!$N:$N,"<>",发射纪录!$D:$D,"="&CLEAN(火箭年間統計!E$6)) -> 0 | F50: =COUNTIFS(发射纪录!$B:$B,"<>-",发射纪录!$G:$G,">="&DATE(YEAR($A50),1,1),发射纪录!$G:$G,"<="&DATE(YEAR($A50),12,31),发射纪录!$N:$N,"<>",发射纪录!$D:$D,"="&CLEAN(火箭年間統計!F$6)) -> 0 | G50: 0 | H50: 3 | I50: 0 | J50: 0 | K50: 0 | L50: 3 | M50: 1 | N50: 4 | O50: 0 | P50: 1 | Q50: 3 | R50: 0 | S50: 0 | T50: 0 | U50: 0 | V50: 0 | W50: 0 | X50: 0 | Y50: 0 | Z50: 0 | AA50: 0 | AB50: 0 | AC50: 0 | AD50: 0 | AE50: 0 | AF50: 0 | AG50: 0 | AH50: 0 | AI50: 0 | AJ50: 0 | AK50: 0 | AL50: 0 | AM50: 0 | AN50: 0 | AO50: 0 | AP50: 0 | AQ50: 0 | AR50: 0 | AS50: 0 | AT50: 0 | AU50: 0 | AV50: 0 | AW50: 0 | AX50: 0 | AY50: 0 | AZ50: 0 | BA50: 0 | BB50: 0 | BC50: 0 | BD50: 0 | BE50: 0 | BF50: 0 | BG50: 0 | BH50: 0
A51: 40544 | B51: =C51+AJ51 -> 19 | C51: 19 | D51: =COUNTIFS(发射纪录!$B:$B,"<>-",发射纪录!$G:$G,">="&DATE(YEAR($A51),1,1),发射纪录!$G:$G,"<="&DATE(YEAR($A51),12,31),发射纪录!$N:$N,"<>",发射纪录!$D:$D,"="&CLEAN(火箭年間統計!D$6)) -> 0 | E51: =COUNTIFS(发射纪录!$B:$B,"<>-",发射纪录!$G:$G,">="&DATE(YEAR($A51),1,1),发射纪录!$G:$G,"<="&DATE(YEAR($A51),12,31),发射纪录!$N:$N,"<>",发射纪录!$D:$D,"="&CLEAN(火箭年間統計!E$6)) -> 0 | F51: =COUNTIFS(发射纪录!$B:$B,"<>-",发射纪录!$G:$G,">="&DATE(YEAR($A51),1,1),发射纪录!$G:$G,"<="&DATE(YEAR($A51),12,31),发射纪录!$N:$N,"<>",发射纪录!$D:$D,"="&CLEAN(火箭年間統計!F$6)) -> 0 | G51: =COUNTIFS(发射纪录!$B:$B,"<>-",发射纪录!$G:$G,">="&DATE(YEAR($A51),1,1),发射纪录!$G:$G,"<="&DATE(YEAR($A51),12,31),发射纪录!$N:$N,"<>",发射纪录!$D:$D,"="&CLEAN(火箭年間統計!G$6)) -> 4 | H51: =COUNTIFS(发射纪录!$B:$B,"<>-",发射纪录!$G:$G,">="&DATE(YEAR($A51),1,1),发射纪录!$G:$G,"<="&DATE(YEAR($A51),12,31),发射纪录!$N:$N,"<>",发射纪录!$D:$D,"="&CLEAN(火箭年間統計!H$6)) -> 1 | I51: =COUNTIFS(发射纪录!$B:$B,"<>-",发射纪录!$G:$G,">="&DATE(YEAR($A51),1,1),发射纪录!$G:$G,"<="&DATE(YEAR($A51),12,31),发射纪录!$N:$N,"<>",发射纪录!$D:$D,"="&CLEAN(火箭年間統計!I$6)) -> 0 | J51: =COUNTIFS(发射纪录!$B:$B,"<>-",发射纪录!$G:$G,">="&DATE(YEAR($A51),1,1),发射纪录!$G:$G,"<="&DATE(YEAR($A51),12,31),发射纪录!$N:$N,"<>",发射纪录!$D:$D,"="&CLEAN(火箭年間統計!J$6)) -> 2 | K51: =COUNTIFS(发射纪录!$B:$B,"<>-",发射纪录!$G:$G,">="&DATE(YEAR($A51),1,1),发射纪录!$G:$G,"<="&DATE(YEAR($A51),12,31),发射纪录!$N:$N,"<>",发射纪录!$D:$D,"="&CLEAN(火箭年間統計!K$6)) -> 0 | L51: =COUNTIFS(发射纪录!$B:$B,"<>-",发射纪录!$G:$G,">="&DATE(YEAR($A51),1,1),发射纪录!$G:$G,"<="&DATE(YEAR($A51),12,31),发射纪录!$N:$N,"<>",发射纪录!$D:$D,"="&CLEAN(火箭年間統計!L$6)) -> 3 | M51: 5 | N51: 1 | O51: 0 | P51: 3 | Q51: 0 | R51: 0 | S51: 0 | T51: 0 | U51: 0 | V51: 0 | W51: 0 | X51: 0 | Y51: 0 | Z51: 0 | AA51: 0 | AB51: 0 | AC51: 0 | AD51: 0 | AE51: 0 | AF51: 0 | AG51: 0 | AH51: 0 | AI51: 0 | AJ51: 0 | AK51: 0 | AL51: 0 | AM51: 0 | AN51: 0 | AO51: 0 | AP51: 0 | AQ51: 0 | AR51: 0 | AS51: 0 | AT51: 0 | AU51: 0 | AV51: 0 | AW51: 0 | AX51: 0 | AY51: 0 | AZ51: 0 | BA51: 0 | BB51: 0 | BC51: 0 | BD51: 0 | BE51: 0 | BF51: 0 | BG51: 0 | BH51: 0
A52: 40909 | B52: =C52+AJ52 -> 19 | C52: 19 | D52: =COUNTIFS(发射纪录!$B:$B,"<>-",发射纪录!$G:$G,">="&DATE(YEAR($A52),1,1),发射纪录!$G:$G,"<="&DATE(YEAR($A52),12,31),发射纪录!$N:$N,"<>",发射纪录!$D:$D,"="&CLEAN(火箭年間統計!D$6)) -> 0 | E52: =COUNTIFS(发射纪录!$B:$B,"<>-",发射纪录!$G:$G,">="&DATE(YEAR($A52),1,1),发射纪录!$G:$G,"<="&DATE(YEAR($A52),12,31),发射纪录!$N:$N,"<>",发射纪录!$D:$D,"="&CLEAN(火箭年間統計!E$6)) -> 0 | F52: =COUNTIFS(发射纪录!$B:$B,"<>-",发射纪录!$G:$G,">="&DATE(YEAR($A52),1,1),发射纪录!$G:$G,"<="&DATE(YEAR($A52),12,31),发射纪录!$N:$N,"<>",发射纪录!$D:$D,"="&CLEAN(火箭年間統計!F$6)) -> 0 | G52: =COUNTIFS(发射纪录!$B:$B,"<>-",发射纪录!$G:$G,">="&DATE(YEAR($A52),1,1),发射纪录!$G:$G,"<="&DATE(YEAR($A52),12,31),发射纪录!$N:$N,"<>",发射纪录!$D:$D,"="&CLEAN(火箭年間統計!G$6)) -> 2 | H52: =COUNTIFS(发射纪录!$B:$B,"<>-",发射纪录!$G:$G,">="&DATE(YEAR($A52),1,1),发射纪录!$G:$G,"<="&DATE(YEAR($A52),12,31),发射纪录!$N:$N,"<>",发射纪录!$D:$D,"="&CLEAN(火箭年間統計!H$6)) -> 3 | I52: =COUNTIFS(发射纪录!$B:$B,"<>-",发射纪录!$G:$G,">="&DATE(YEAR($A52),1,1),发射纪录!$G:$G,"<="&DATE(YEAR($A52),12,31),发射纪录!$N:$N,"<>",发射纪录!$D:$D,"="&CLEAN(火箭年間統計!I$6)) -> 0 | J52: =COUNTIFS(发射纪录!$B:$B,"<>-",发射纪录!$G:$G,">="&DATE(YEAR($A52),1,1),发射纪录!$G:$G,"<="&DATE(YEAR($A52),12,31),发射纪录!$N:$N,"<>",发射纪录!$D:$D,"="&CLEAN(火箭年間統計!J$6)) -> 1 | K52: =COUNTIFS(发射纪录!$B:$B,"<>-",发射纪录!$G:$G,">="&DATE(YEAR($A52),1,1),发射纪录!$G:$G,"<="&DATE(YEAR($A52),12,31),发射纪录!$N:$N,"<>",发射纪录!$D:$D,"="&CLEAN(火箭年間統計!K$6)) -> 0 | L52: =COUNTIFS(发射纪录!$B:$B,"<>-",发射纪录!$G:$G,">="&DATE(YEAR($A52),1,1),发射纪录!$G:$G,"<="&DATE(YEAR($A52),12,31),发射纪录!$N:$N,"<>",发射纪录!$D:$D,"="&CLEAN(火箭年間統計!L$6)) -> 1 | M52: 5 | N52: 3 | O52: 0 | P52: 2 | Q52: 2 | R52: 0 | S52: 0 | T52: 0 | U52: 0 | V52: 0 | W52: 0 | X52: 0 | Y52: 0 | Z52: 0 | AA52: 0 | AB52: 0 | AC52: 0 | AD52: 0 | AE52: 0 | AF52: 0 | AG52: 0 | AH52: 0 | AI52: 0 | AJ52: 0 | AK52: 0 | AL52: 0 | AM52: 0 | AN52: 0 | AO52: 0 | AP52: 0 | AQ52: 0 | AR52: 0 | AS52: 0 | AT52: 0 | AU52: 0 | AV52: 0 | AW52: 0 | AX52: 0 | AY52: 0 | AZ52: 0 | BA52: 0 | BB52: 0 | BC52: 0 | BD52: 0 | BE52: 0 | BF52: 0 | BG52: 0 | BH52: 0
A53: 41275 | B53: =C53+AJ53 -> 15 | C53: 14 | D53: =COUNTIFS(发射纪录!$B:$B,"<>-",发射纪录!$G:$G,">="&DATE(YEAR($A53),1,1),发射纪录!$G:$G,"<="&DATE(YEAR($A53),12,31),发射纪录!$N:$N,"<>",发射纪录!$D:$D,"="&CLEAN(火箭年間統計!D$6)) -> 0 | E53: =COUNTIFS(发射纪录!$B:$B,"<>-",发射纪录!$G:$G,">="&DATE(YEAR($A53),1,1),发射纪录!$G:$G,"<="&DATE(YEAR($A53),12,31),发射纪录!$N:$N,"<>",发射纪录!$D:$D,"="&CLEAN(火箭年間統計!E$6)) -> 0 | F53: =COUNTIFS(发射纪录!$B:$B,"<>-",发射纪录!$G:$G,">="&DATE(YEAR($A53),1,1),发射纪录!$G:$G,"<="&DATE(YEAR($A53),12,31),发射纪录!$N:$N,"<>",发射纪录!$D:$D,"="&CLEAN(火箭年間統計!F$6)) -> 0 | G53: =COUNTIFS(发射纪录!$B:$B,"<>-",发射纪录!$G:$G,">="&DATE(YEAR($A53),1,1),发射纪录!$G:$G,"<="&DATE(YEAR($A53),12,31),发射纪录!$N:$N,"<>",发射纪录!$D:$D,"="&CLEAN(火箭年間統計!G$6)) -> 2 | H53: =COUNTIFS(发射纪录!$B:$B,"<>-",发射纪录!$G:$G,">="&DATE(YEAR($A53),1,1),发射纪录!$G:$G,"<="&DATE(YEAR($A53),12,31),发射纪录!$N:$N,"<>",发射纪录!$D:$D,"="&CLEAN(火箭年間統計!H$6)) -> 2 | I53: =COUNTIFS(发射纪录!$B:$B,"<>-",发射纪录!$G:$G,">="&DATE(YEAR($A53),1,1),发射纪录!$G:$G,"<="&DATE(YEAR($A53),12,31),发射纪录!$N:$N,"<>",发射纪录!$D:$D,"="&CLEAN(火箭年間統計!I$6)) -> 0 | J53: =COUNTIFS(发射纪录!$B:$B,"<>-",发射纪录!$G:$G,">="&DATE(YEAR($A53),1,1),发射纪录!$G:$G,"<="&DATE(YEAR($A53),12,31),发射纪录!$N:$N,"<>",发射纪录!$D:$D,"="&CLEAN(火箭年間統計!J$6)) -> 1 | K53: =COUNTIFS(发射纪录!$B:$B,"<>-",发射纪录!$G:$G,">="&DATE(YEAR($A53),1,1),发射纪录!$G:$G,"<="&DATE(YEAR($A53),12,31),发射纪录!$N:$N,"<>",发射纪录!$D:$D,"="&CLEAN(火箭年間統計!K$6)) -> 0 | L53: =COUNTIFS(发射纪录!$B:$B,"<>-",发射纪录!$G:$G,">="&DATE(YEAR($A53),1,1),发射纪录!$G:$G,"<="&DATE(YEAR($A53),12,31),发射纪录!$N:$N,"<>",发射纪录!$D:$D,"="&CLEAN(火箭年間統計!L$6)) -> 0 | M53: 3 | N53: 0 | O53: 0 | P53: 2 | Q53: 4 | R53: 0 | S53: 0 | T53: 0 | U53: 0 | V53: 0 | W53: 0 | X53: 0 | Y53: 0 | Z53: 0 | AA53: 0 | AB53: 0 | AC53: 0 | AD53: 0 | AE53: 0 | AF53: 0 | AG53: 0 | AH53: 0 | AI53: 0 | AJ53: 1 | AK53: 0 | AL53: 0 | AM53: 0 | AN53: 1 | AO53: 0 | AP53: 0 | AQ53: 0 | AR53: 0 | AS53: 0 | AT53: 0 | AU53: 0 | AV53: 0 | AW53: 0 | AX53: 0 | AY53: 0 | AZ53: 0 | BA53: 0 | BB53: 0 | BC53: 0 | BD53: 0 | BE53: 0 | BF53: 0 | BG53: 0 | BH53: 0
A54: 41640 | B54: =C54+AJ54 -> 16 | C54: 15 | D54: =COUNTIFS(发射纪录!$B:$B,"<>-",发射纪录!$G:$G,">="&DATE(YEAR($A54),1,1),发射纪录!$G:$G,"<="&DATE(YEAR($A54),12,31),发射纪录!$N:$N,"<>",发射纪录!$D:$D,"="&CLEAN(火箭年間統計!D$6)) -> 0 | E54: =COUNTIFS(发射纪录!$B:$B,"<>-",发射纪录!$G:$G,">="&DATE(YEAR($A54),1,1),发射纪录!$G:$G,"<="&DATE(YEAR($A54),12,31),发射纪录!$N:$N,"<>",发射纪录!$D:$D,"="&CLEAN(火箭年間統計!E$6)) -> 0 | F54: =COUNTIFS(发射纪录!$B:$B,"<>-",发射纪录!$G:$G,">="&DATE(YEAR($A54),1,1),发射纪录!$G:$G,"<="&DATE(YEAR($A54),12,31),发射纪录!$N:$N,"<>",发射纪录!$D:$D,"="&CLEAN(火箭年間統計!F$6)) -> 0 | G54: =COUNTIFS(发射纪录!$B:$B,"<>-",发射纪录!$G:$G,">="&DATE(YEAR($A54),1,1),发射纪录!$G:$G,"<="&DATE(YEAR($A54),12,31),发射纪录!$N:$N,"<>",发射纪录!$D:$D,"="&CLEAN(火箭年間統計!G$6)) -> 4 | H54: =COUNTIFS(发射纪录!$B:$B,"<>-",发射纪录!$G:$G,">="&DATE(YEAR($A54),1,1),发射纪录!$G:$G,"<="&DATE(YEAR($A54),12,31),发射纪录!$N:$N,"<>",发射纪录!$D:$D,"="&CLEAN(火箭年間統計!H$6)) -> 2 | I54: =COUNTIFS(发射纪录!$B:$B,"<>-",发射纪录!$G:$G,">="&DATE(YEAR($A54),1,1),发射纪录!$G:$G,"<="&DATE(YEAR($A54),12,31),发射纪录!$N:$N,"<>",发射纪录!$D:$D,"="&CLEAN(火箭年間統計!I$6)) -> 0 | J54: =COUNTIFS(发射纪录!$B:$B,"<>-",发射纪录!$G:$G,">="&DATE(YEAR($A54),1,1),发射纪录!$G:$G,"<="&DATE(YEAR($A54),12,31),发射纪录!$N:$N,"<>",发射纪录!$D:$D,"="&CLEAN(火箭年間統計!J$6)) -> 0 | K54: =COUNTIFS(发射纪录!$B:$B,"<>-",发射纪录!$G:$G,">="&DATE(YEAR($A54),1,1),发射纪录!$G:$G,"<="&DATE(YEAR($A54),12,31),发射纪录!$N:$N,"<>",发射纪录!$D:$D,"="&CLEAN(火箭年間統計!K$6)) -> 0 | L54: =COUNTIFS(发射纪录!$B:$B,"<>-",发射纪录!$G:$G,">="&DATE(YEAR($A54),1,1),发射纪录!$G:$G,"<="&DATE(YEAR($A54),12,31),发射纪录!$N:$N,"<>",发射纪录!$D:$D,"="&CLEAN(火箭年間統計!L$6)) -> 1 | M54: 0 | N54: 1 | O54: 0 | P54: 4 | Q54: 3 | R54: 0 | S54: 0 | T54: 0 | U54: 0 | V54: 0 | W54: 0 | X54: 0 | Y54: 0 | Z54: 0 | AA54: 0 | AB54: 0 | AC54: 0 | AD54: 0 | AE54: 0 | AF54: 0 | AG54: 0 | AH54: 0 | AI54: 0 | AJ54: 1 | AK54: 0 | AL54: 0 | AM54: 0 | AN54: 1 | AO54: 0 | AP54: 0 | AQ54: 0 | AR54: 0 | AS54: 0 | AT54: 0 | AU54: 0 | AV54: 0 | AW54: 0 | AX54: 0 | AY54: 0 | AZ54: 0 | BA54: 0 | BB54: 0 | BC54: 0 | BD54: 0 | BE54: 0 | BF54: 0 | BG54: 0 | BH54: 0
A55: 42005 | B55: =C55+AJ55 -> 19 | C55: 19 | D55: =COUNTIFS(发射纪录!$B:$B,"<>-",发射纪录!$G:$G,">="&DATE(YEAR($A55),1,1),发射纪录!$G:$G,"<="&DATE(YEAR($A55),12,31),发射纪录!$N:$N,"<>",发射纪录!$D:$D,"="&CLEAN(火箭年間統計!D$6)) -> 0 | E55: =COUNTIFS(发射纪录!$B:$B,"<>-",发射纪录!$G:$G,">="&DATE(YEAR($A55),1,1),发射纪录!$G:$G,"<="&DATE(YEAR($A55),12,31),发射纪录!$N:$N,"<>",发射纪录!$D:$D,"="&CLEAN(火箭年間統計!E$6)) -> 0 | F55: =COUNTIFS(发射纪录!$B:$B,"<>-",发射纪录!$G:$G,">="&DATE(YEAR($A55),1,1),发射纪录!$G:$G,"<="&DATE(YEAR($A55),12,31),发射纪录!$N:$N,"<>",发射纪录!$D:$D,"="&CLEAN(火箭年間統計!F$6)) -> 0 | G55: =COUNTIFS(发射纪录!$B:$B,"<>-",发射纪录!$G:$G,">="&DATE(YEAR($A55),1,1),发射纪录!$G:$G,"<="&DATE(YEAR($A55),12,31),发射纪录!$N:$N,"<>",发射纪录!$D:$D,"="&CLEAN(火箭年間統計!G$6)) -> 0 | H55: =COUNTIFS(发射纪录!$B:$B,"<>-",发射纪录!$G:$G,">="&DATE(YEAR($A55),1,1),发射纪录!$G:$G,"<="&DATE(YEAR($A55),12,31),发射纪录!$N:$N,"<>",发射纪录!$D:$D,"="&CLEAN(火箭年間統計!H$6)) -> 4 | I55: =COUNTIFS(发射纪录!$B:$B,"<>-",发射纪录!$G:$G,">="&DATE(YEAR($A55),1,1),发射纪录!$G:$G,"<="&DATE(YEAR($A55),12,31),发射纪录!$N:$N,"<>",发射纪录!$D:$D,"="&CLEAN(火箭年間統計!I$6)) -> 0 | J55: =COUNTIFS(发射纪录!$B:$B,"<>-",发射纪录!$G:$G,">="&DATE(YEAR($A55),1,1),发射纪录!$G:$G,"<="&DATE(YEAR($A55),12,31),发射纪录!$N:$N,"<>",发射纪录!$D:$D,"="&CLEAN(火箭年間統計!J$6)) -> 0 | K55: =COUNTIFS(发射纪录!$B:$B,"<>-",发射纪录!$G:$G,">="&DATE(YEAR($A55),1,1),发射纪录!$G:$G,"<="&DATE(YEAR($A55),12,31),发射纪录!$N:$N,"<>",发射纪录!$D:$D,"="&CLEAN(火箭年間統計!K$6)) -> 0 | L55: =COUNTIFS(发射纪录!$B:$B,"<>-",发射纪录!$G:$G,">="&DATE(YEAR($A55),1,1),发射纪录!$G:$G,"<="&DATE(YEAR($A55),12,31),发射纪录!$N:$N,"<>",发射纪录!$D:$D,"="&CLEAN(火箭年間統計!L$6)) -> 0 | M55: 8 | N55: 1 | O55: 0 | P55: 2 | Q55: 2 | R55: 0 | S55: 0 | T55: 1 | U55: 0 | V55: 0 | W55: 0 | X55: 0 | Y55: 0 | Z55: 0 | AA55: 0 | AB55: 0 | AC55: 0 | AD55: 1 | AE55: 0 | AF55: 0 | AG55: 0 | AH55: 0 | AI55: 0 | AJ55: 0 | AK55: 0 | AL55: 0 | AM55: 0 | AN55: 0 | AO55: 0 | AP55: 0 | AQ55: 0 | AR55: 0 | AS55: 0 | AT55: 0 | AU55: 0 | AV55: 0 | AW55: 0 | AX55: 0 | AY55: 0 | AZ55: 0 | BA55: 0 | BB55: 0 | BC55: 0 | BD55: 0 | BE55: 0 | BF55: 0 | BG55: 0 | BH55: 0
A56: 42370 | B56: =C56+AJ56 -> 22 | C56: 22 | D56: =COUNTIFS(发射纪录!$B:$B,"<>-",发射纪录!$G:$G,">="&DATE(YEAR($A56),1,1),发射纪录!$G:$G,"<="&DATE(YEAR($A56),12,31),发射纪录!$N:$N,"<>",发射纪录!$D:$D,"="&CLEAN(火箭年間統計!D$6)) -> 0 | E56: =COUNTIFS(发射纪录!$B:$B,"<>-",发射纪录!$G:$G,">="&DATE(YEAR($A56),1,1),发射纪录!$G:$G,"<="&DATE(YEAR($A56),12,31),发射纪录!$N:$N,"<>",发射纪录!$D:$D,"="&CLEAN(火箭年間統計!E$6)) -> 0 | F56: =COUNTIFS(发射纪录!$B:$B,"<>-",发射纪录!$G:$G,">="&DATE(YEAR($A56),1,1),发射纪录!$G:$G,"<="&DATE(YEAR($A56),12,31),发射纪录!$N:$N,"<>",发射纪录!$D:$D,"="&CLEAN(火箭年間統計!F$6)) -> 0 | G56: =COUNTIFS(发射纪录!$B:$B,"<>-",发射纪录!$G:$G,">="&DATE(YEAR($A56),1,1),发射纪录!$G:$G,"<="&DATE(YEAR($A56),12,31),发射纪录!$N:$N,"<>",发射纪录!$D:$D,"="&CLEAN(火箭年間統計!G$6)) -> 0 | H56: =COUNTIFS(发射纪录!$B:$B,"<>-",发射纪录!$G:$G,">="&DATE(YEAR($A56),1,1),发射纪录!$G:$G,"<="&DATE(YEAR($A56),12,31),发射纪录!$N:$N,"<>",发射纪录!$D:$D,"="&CLEAN(火箭年間統計!H$6)) -> 6 | I56: =COUNTIFS(发射纪录!$B:$B,"<>-",发射纪录!$G:$G,">="&DATE(YEAR($A56),1,1),发射纪录!$G:$G,"<="&DATE(YEAR($A56),12,31),发射纪录!$N:$N,"<>",发射纪录!$D:$D,"="&CLEAN(火箭年間統計!I$6)) -> 0 | J56: =COUNTIFS(发射纪录!$B:$B,"<>-",发射纪录!$G:$G,">="&DATE(YEAR($A56),1,1),发射纪录!$G:$G,"<="&DATE(YEAR($A56),12,31),发射纪录!$N:$N,"<>",发射纪录!$D:$D,"="&CLEAN(火箭年間統計!J$6)) -> 2 | K56: =COUNTIFS(发射纪录!$B:$B,"<>-",发射纪录!$G:$G,">="&DATE(YEAR($A56),1,1),发射纪录!$G:$G,"<="&DATE(YEAR($A56),12,31),发射纪录!$N:$N,"<>",发射纪录!$D:$D,"="&CLEAN(火箭年間統計!K$6)) -> 0 | L56: =COUNTIFS(发射纪录!$B:$B,"<>-",发射纪录!$G:$G,">="&DATE(YEAR($A56),1,1),发射纪录!$G:$G,"<="&DATE(YEAR($A56),12,31),发射纪录!$N:$N,"<>",发射纪录!$D:$D,"="&CLEAN(火箭年間統計!L$6)) -> 1 | M56: 3 | N56: 3 | O56: 0 | P56: 2 | Q56: 2 | R56: 1 | S56: 0 | T56: 0 | U56: 0 | V56: 0 | W56: 1 | X56: 0 | Y56: 0 | Z56: 0 | AA56: 0 | AB56: 0 | AC56: 0 | AD56: 1 | AE56: 0 | AF56: 0 | AG56: 0 | AH56: 0 | AI56: 0 | AJ56: 0 | AK56: 0 | AL56: 0 | AM56: 0 | AN56: 0 | AO56: 0 | AP56: 0 | AQ56: 0 | AR56: 0 | AS56: 0 | AT56: 0 | AU56: 0 | AV56: 0 | AW56: 0 | AX56: 0 | AY56: 0 | AZ56: 0 | BA56: 0 | BB56: 0 | BC56: 0 | BD56: 0 | BE56: 0 | BF56: 0 | BG56: 0 | BH56: 0
A57: 42736 | B57: =C57+AJ57 -> 18 | C57: 16 | D57: =COUNTIFS(发射纪录!$B:$B,"<>-",发射纪录!$G:$G,">="&DATE(YEAR($A57),1,1),发射纪录!$G:$G,"<="&DATE(YEAR($A57),12,31),发射纪录!$N:$N,"<>",发射纪录!$D:$D,"="&CLEAN(火箭年間統計!D$6)) -> 0 | E57: =COUNTIFS(发射纪录!$B:$B,"<>-",发射纪录!$G:$G,">="&DATE(YEAR($A57),1,1),发射纪录!$G:$G,"<="&DATE(YEAR($A57),12,31),发射纪录!$N:$N,"<>",发射纪录!$D:$D,"="&CLEAN(火箭年間統計!E$6)) -> 0 | F57: =COUNTIFS(发射纪录!$B:$B,"<>-",发射纪录!$G:$G,">="&DATE(YEAR($A57),1,1),发射纪录!$G:$G,"<="&DATE(YEAR($A57),12,31),发射纪录!$N:$N,"<>",发射纪录!$D:$D,"="&CLEAN(火箭年間統計!F$6)) -> 0 | G57: =COUNTIFS(发射纪录!$B:$B,"<>-",发射纪录!$G:$G,">="&DATE(YEAR($A57),1,1),发射纪录!$G:$G,"<="&DATE(YEAR($A57),12,31),发射纪录!$N:$N,"<>",发射纪录!$D:$D,"="&CLEAN(火箭年間統計!G$6)) -> 3 | H57: =COUNTIFS(发射纪录!$B:$B,"<>-",发射纪录!$G:$G,">="&DATE(YEAR($A57),1,1),发射纪录!$G:$G,"<="&DATE(YEAR($A57),12,31),发射纪录!$N:$N,"<>",发射纪录!$D:$D,"="&CLEAN(火箭年間統計!H$6)) -> 3 | I57: =COUNTIFS(发射纪录!$B:$B,"<>-",发射纪录!$G:$G,">="&DATE(YEAR($A57),1,1),发射纪录!$G:$G,"<="&DATE(YEAR($A57),12,31),发射纪录!$N:$N,"<>",发射纪录!$D:$D,"="&CLEAN(火箭年間統計!I$6)) -> 0 | J57: =COUNTIFS(发射纪录!$B:$B,"<>-",发射纪录!$G:$G,">="&DATE(YEAR($A57),1,1),发射纪录!$G:$G,"<="&DATE(YEAR($A57),12,31),发射纪录!$N:$N,"<>",发射纪录!$D:$D,"="&CLEAN(火箭年間統計!J$6)) -> 0 | K57: =COUNTIFS(发射纪录!$B:$B,"<>-",发射纪录!$G:$G,">="&DATE(YEAR($A57),1,1),发射纪录!$G:$G,"<="&DATE(YEAR($A57),12,31),发射纪录!$N:$N,"<>",发射纪录!$D:$D,"="&CLEAN(火箭年間統計!K$6)) -> 0 | L57: =COUNTIFS(发射纪录!$B:$B,"<>-",发射纪录!$G:$G,">="&DATE(YEAR($A57),1,1),发射纪录!$G:$G,"<="&DATE(YEAR($A57),12,31),发射纪录!$N:$N,"<>",发射纪录!$D:$D,"="&CLEAN(火箭年間統計!L$6)) -> 0 | M57: 5 | N57: 0 | O57: 0 | P57: 1 | Q57: 1 | R57: 1 | S57: 0 | T57: 1 | U57: 0 | V57: 0 | W57: 1 | X57: 0 | Y57: 0 | Z57: 0 | AA57: 0 | AB57: 0 | AC57: 0 | AD57: 0 | AE57: 0 | AF57: 0 | AG57: 0 | AH57: 0 | AI57: 0 | AJ57: 2 | AK57: 0 | AL57: 0 | AM57: 1 | AN57: 0 | AO57: 1 | AP57: 0 | AQ57: 0 | AR57: 0 | AS57: 0 | AT57: 0 | AU57: 0 | AV57: 0 | AW57: 0 | AX57: 0 | AY57: 0 | AZ57: 0 | BA57: 0 | BB57: 0 | BC57: 0 | BD57: 0 | BE57: 0 | BF57: 0 | BG57: 0 | BH57: 0
